<?xml version="1.0" encoding="utf-8"?>
<!-- This URDF was automatically created by SolidWorks to URDF Exporter! Originally created by Stephen Brawner (brawner@gmail.com) 
     Commit Version: 1.6.0-4-g7f85cfe  Build Version: 1.6.7995.38578
     For more information, please see http://wiki.ros.org/sw_urdf_exporter -->
<robot
  name="apex_hand_right">
  <link
    name="right_palm_link">
    <inertial>
      <origin
        xyz="-0.0041511 -8.4584E-06 0.069666"
        rpy="0 0 0" />
      <mass
        value="0.2" />
      <inertia
        ixx="0.00021791"
        ixy="9.4466E-08"
        ixz="-2.4439E-06"
        iyy="0.00015713"
        iyz="-3.5054E-06"
        izz="9.7461E-05" />
    </inertial>
    <visual>
      <origin
        xyz="0 0 0"
        rpy="0 0 0" />
      <geometry>
        <mesh
          filename="./meshes/right_palm_link.STL" />
      </geometry>
      <material
        name="">
        <color
          rgba="0.61176 0.65882 0.67059 1" />
      </material>
    </visual>
    <collision>
      <origin
        xyz="0 0 0"
        rpy="0 0 0" />
      <geometry>
        <mesh
          filename="./meshes/right_palm_link.STL" />
      </geometry>
    </collision>
  </link>
  <link
    name="right_palm_base">
    <inertial>
      <origin
        xyz="-0.01088 0.00011297 0.073476"
        rpy="0 0 0" />
      <mass
        value="0.1" />
      <inertia
        ixx="0.00015882"
        ixy="-3.1605E-07"
        ixz="-1.7871E-06"
        iyy="0.00012667"
        iyz="-6.3568E-07"
        izz="6.0881E-05" />
    </inertial>
    <visual>
      <origin
        xyz="0 0 0"
        rpy="0 0 0" />
      <geometry>
        <mesh
          filename="./meshes/right_palm_base.STL" />
      </geometry>
      <material
        name="">
        <color
          rgba="0.61176 0.65882 0.67059 1" />
      </material>
    </visual>
    <collision>
      <origin
        xyz="0 0 0"
        rpy="0 0 0" />
      <geometry>
        <mesh
          filename="./meshes/right_palm_base.STL" />
      </geometry>
    </collision>
  </link>
  <joint
    name="right_palm_base_fix"
    type="fixed">
    <origin
      xyz="0 0 0"
      rpy="0 0 0" />
    <parent
      link="right_palm_link" />
    <child
      link="right_palm_base" />
    <axis
      xyz="0 0 0" />
  </joint>
  <link
    name="right_thumb_link0">
    <inertial>
      <origin
        xyz="0.0074473 2.0817E-17 0.00067548"
        rpy="0 0 0" />
      <mass
        value="0.01096758" />
      <inertia
        ixx="3.0147E-07"
        ixy="4.0582E-23"
        ixz="1.2544E-08"
        iyy="2.6685E-07"
        iyz="3.8245E-22"
        izz="2.1799E-07" />
    </inertial>
    <visual>
      <origin
        xyz="0 0 0"
        rpy="0 0 0" />
      <geometry>
        <mesh
          filename="./meshes/right_thumb_link0.STL" />
      </geometry>
      <material
        name="">
        <color
          rgba="0.61176 0.65882 0.67059 1" />
      </material>
    </visual>
    <collision>
      <origin
        xyz="0 0 0"
        rpy="0 0 0" />
      <geometry>
        <mesh
          filename="./meshes/right_thumb_link0.STL" />
      </geometry>
    </collision>
  </link>
  <joint
    name="right_thumb_j0"
    type="revolute">
    <origin
      xyz="0.013 0.023 0.0493"
      rpy="3.1416 0 1.5708" />
    <parent
      link="right_palm_base" />
    <child
      link="right_thumb_link0" />
    <axis
      xyz="0 0 1" />
    <limit
      lower="0"
      upper="1.5707"
      effort="0"
      velocity="0" />
  </joint>
  <link
    name="right_thumb_link1">
    <inertial>
      <origin
        xyz="-2.4803E-05 2.7756E-17 0.008472"
        rpy="0 0 0" />
      <mass
        value="0.01551203" />
      <inertia
        ixx="4.7331E-07"
        ixy="-1.3137E-23"
        ixz="-8.51E-10"
        iyy="4.003E-07"
        iyz="-4.7609E-22"
        izz="2.6418E-07" />
    </inertial>
    <visual>
      <origin
        xyz="0 0 0"
        rpy="0 0 0" />
      <geometry>
        <mesh
          filename="./meshes/right_thumb_link1.STL" />
      </geometry>
      <material
        name="">
        <color
          rgba="0.61176 0.65882 0.67059 1" />
      </material>
    </visual>
    <collision>
      <origin
        xyz="0 0 0"
        rpy="0 0 0" />
      <geometry>
        <mesh
          filename="./meshes/right_thumb_link1.STL" />
      </geometry>
    </collision>
  </link>
  <joint
    name="right_thumb_j1"
    type="revolute">
    <origin
      xyz="0.0145 0 0"
      rpy="-1.5708 0 -1.5708" />
    <parent
      link="right_thumb_link0" />
    <child
      link="right_thumb_link1" />
    <axis
      xyz="0 0 1" />
    <limit
      lower="-0.1745"
      upper="1.0471"
      effort="0"
      velocity="0" />
  </joint>
  <link
    name="right_thumb_link2">
    <inertial>
      <origin
        xyz="-0.0062375 -0.026602 -3.7639E-05"
        rpy="0 0 0" />
      <mass
        value="0.0324231" />
      <inertia
        ixx="7.1811E-06"
        ixy="4.3998E-07"
        ixz="-2.2353E-09"
        iyy="2.6125E-06"
        iyz="-1.9175E-08"
        izz="7.8196E-06" />
    </inertial>
    <visual>
      <origin
        xyz="0 0 0"
        rpy="0 0 0" />
      <geometry>
        <mesh
          filename="./meshes/right_thumb_link2.STL" />
      </geometry>
      <material
        name="">
        <color
          rgba="0.61176 0.65882 0.67059 1" />
      </material>
    </visual>
    <collision>
      <origin
        xyz="0 0 0"
        rpy="0 0 0" />
      <geometry>
        <mesh
          filename="./meshes/right_thumb_link2.STL" />
      </geometry>
    </collision>
  </link>
  <joint
    name="right_thumb_j2"
    type="revolute">
    <origin
      xyz="0 0 0.014"
      rpy="-1.5708 0 1.5708" />
    <parent
      link="right_thumb_link1" />
    <child
      link="right_thumb_link2" />
    <axis
      xyz="0 0 1" />
    <limit
      lower="0"
      upper="1.396"
      effort="0"
      velocity="0" />
  </joint>
  <link
    name="right_thumb_link3">
    <inertial>
      <origin
        xyz="0.014953 -0.0017905 4.9291E-05"
        rpy="0 0 0" />
      <mass
        value="0.018383721" />
      <inertia
        ixx="3.7794E-07"
        ixy="-1.6786E-09"
        ixz="1.8891E-09"
        iyy="1.2258E-06"
        iyz="3.0324E-09"
        izz="1.1706E-06" />
    </inertial>
    <visual>
      <origin
        xyz="0 0 0"
        rpy="0 0 0" />
      <geometry>
        <mesh
          filename="./meshes/right_thumb_link3.STL" />
      </geometry>
      <material
        name="">
        <color
          rgba="0.61176 0.65882 0.67059 1" />
      </material>
    </visual>
    <collision>
      <origin
        xyz="0 0 0"
        rpy="0 0 0" />
      <geometry>
        <mesh
          filename="./meshes/right_thumb_link3.STL" />
      </geometry>
    </collision>
  </link>
  <joint
    name="right_thumb_j3"
    type="revolute">
    <origin
      xyz="0 -0.055 0"
      rpy="0 0 -1.5708" />
    <parent
      link="right_thumb_link2" />
    <child
      link="right_thumb_link3" />
    <axis
      xyz="0 0 1" />
    <limit
      lower="-0.349"
      upper="1.396"
      effort="0"
      velocity="0" />
  </joint>
  <link
    name="right_thumb_link4">
    <inertial>
      <origin
        xyz="0.0105 -0.001483 -3.3599E-05"
        rpy="0 0 0" />
      <mass
        value="0.007655847" />
      <inertia
        ixx="1.1521E-07"
        ixy="1.9919E-08"
        ixz="7.1097E-10"
        iyy="3.5053E-07"
        iyz="-6.8431E-10"
        izz="3.4107E-07" />
    </inertial>
    <visual>
      <origin
        xyz="0 0 0"
        rpy="0 0 0" />
      <geometry>
        <mesh
          filename="./meshes/right_thumb_link4.STL" />
      </geometry>
      <material
        name="">
        <color
          rgba="0.61176 0.65882 0.67059 1" />
      </material>
    </visual>
    <collision>
      <origin
        xyz="0 0 0"
        rpy="0 0 0" />
      <geometry>
        <mesh
          filename="./meshes/right_thumb_link4.STL" />
      </geometry>
    </collision>
  </link>
  <joint
    name="right_thumb_j4"
    type="revolute">
    <origin
      xyz="0.03 0 0"
      rpy="0 0 0" />
    <parent
      link="right_thumb_link3" />
    <child
      link="right_thumb_link4" />
    <axis
      xyz="0 0 1" />
    <limit
      lower="-0.349"
      upper="1.396"
      effort="0"
      velocity="0" />
    <mimic joint="right_thumb_j3" multiplier="1.0" offset="0"/>
  </joint>
  <link
    name="right_thumb_tactile2">
    <inertial>
      <origin
        xyz="0.017427 0.0026589 -0.00030846"
        rpy="0 0 0" />
      <mass
        value="0.0098665" />
      <inertia
        ixx="1.3971E-07"
        ixy="2.3661E-08"
        ixz="-3.9506E-11"
        iyy="2.1779E-07"
        iyz="1.0108E-10"
        izz="1.6493E-07" />
    </inertial>
    <visual>
      <origin
        xyz="0 0 0"
        rpy="0 0 0" />
      <geometry>
        <mesh
          filename="./meshes/right_thumb_tactile2.STL" />
      </geometry>
      <material
        name="">
        <color
          rgba="0.61176 0.65882 0.67059 1" />
      </material>
    </visual>
    <collision>
      <origin
        xyz="0 0 0"
        rpy="0 0 0" />
      <geometry>
        <mesh
          filename="./meshes/right_thumb_tactile2.STL" />
      </geometry>
    </collision>
  </link>
  <joint
    name="right_thumb_tactile2_fix"
    type="fixed">
    <origin
      xyz="0 0 0"
      rpy="0 0 0" />
    <parent
      link="right_thumb_link4" />
    <child
      link="right_thumb_tactile2" />
    <axis
      xyz="0 0 0" />
  </joint>
  <link
    name="right_thumb_pad">
    <inertial>
      <origin
        xyz="2.7756E-17 0 -0.00025"
        rpy="0 0 0" />
      <mass
        value="3.927E-07" />
      <inertia
        ixx="3.2725E-14"
        ixy="-4.4842E-44"
        ixz="5.7129E-29"
        iyy="3.2725E-14"
        iyz="1.5931E-58"
        izz="4.9087E-14" />
    </inertial>
    <visual>
      <origin
        xyz="0 0 0"
        rpy="0 0 0" />
      <geometry>
        <mesh
          filename="./meshes/right_thumb_pad.STL" />
      </geometry>
      <material
        name="">
        <color
          rgba="1 0.6 0 1" />
      </material>
    </visual>
    <collision>
      <origin
        xyz="0 0 0"
        rpy="0 0 0" />
      <geometry>
        <mesh
          filename="./meshes/right_thumb_pad.STL" />
      </geometry>
    </collision>
  </link>
  <joint
    name="right_thumb_pad_fix"
    type="fixed">
    <origin
      xyz="0.018471 0.0088124 0"
      rpy="0 0 0" />
    <parent
      link="right_thumb_tactile2" />
    <child
      link="right_thumb_pad" />
    <axis
      xyz="0 0 0" />
  </joint>
  <link
    name="right_thumb_tip">
    <inertial>
      <origin
        xyz="0 2.08166817117217E-17 -0.000124999999999995"
        rpy="0 0 0" />
      <mass
        value="4.90873852123406E-08" />
      <inertia
        ixx="1.02265385859043E-15"
        ixy="-1.40129846432482E-45"
        ixz="1.7852884316822E-30"
        iyy="1.02265385859043E-15"
        iyz="4.97841222228891E-60"
        izz="1.53398078788564E-15" />
    </inertial>
    <visual>
      <origin
        xyz="0 0 0"
        rpy="0 0 0" />
      <geometry>
        <mesh
          filename="./meshes/right_thumb_tip.STL" />
      </geometry>
      <material
        name="">
        <color
          rgba="1 0.6 0 1" />
      </material>
    </visual>
    <collision>
      <origin
        xyz="0 0 0"
        rpy="0 0 0" />
      <geometry>
        <mesh
          filename="./meshes/right_thumb_tip.STL" />
      </geometry>
    </collision>
  </link>
  <joint
    name="right_thumb_tip_fix"
    type="fixed">
    <origin
      xyz="0.029863 -0.00039744 0"
      rpy="0 0 0" />
    <parent
      link="right_thumb_tactile2" />
    <child
      link="right_thumb_tip" />
    <axis
      xyz="0 0 0" />
  </joint>
  <link
    name="right_thumb_tactile1">
    <inertial>
      <origin
        xyz="0.015148 0.0051839 0.00048273"
        rpy="0 0 0" />
      <mass
        value="0.0093845355" />
      <inertia
        ixx="9.9181E-08"
        ixy="-1.0454E-09"
        ixz="1.2408E-10"
        iyy="1.2322E-07"
        iyz="3.0713E-09"
        izz="5.6299E-08" />
    </inertial>
    <visual>
      <origin
        xyz="0 0 0"
        rpy="0 0 0" />
      <geometry>
        <mesh
          filename="./meshes/right_thumb_tactile1.STL" />
      </geometry>
      <material
        name="">
        <color
          rgba="0.61176 0.65882 0.67059 1" />
      </material>
    </visual>
    <collision>
      <origin
        xyz="0 0 0"
        rpy="0 0 0" />
      <geometry>
        <mesh
          filename="./meshes/right_thumb_tactile1.STL" />
      </geometry>
    </collision>
  </link>
  <joint
    name="right_thumb_tactile1_fix"
    type="fixed">
    <origin
      xyz="0 0 0"
      rpy="0 0 0" />
    <parent
      link="right_thumb_link3" />
    <child
      link="right_thumb_tactile1" />
    <axis
      xyz="0 0 0" />
  </joint>
  <link
    name="right_thumb_tactile0">
    <inertial>
      <origin
        xyz="0.0043005 -0.02199 -0.0010257"
        rpy="0 0 0" />
      <mass
        value="0.035995576" />
      <inertia
        ixx="2.2573E-06"
        ixy="2.7497E-09"
        ixz="-2.6799E-08"
        iyy="1.3078E-06"
        iyz="2.1452E-08"
        izz="1.7366E-06" />
    </inertial>
    <visual>
      <origin
        xyz="0 0 0"
        rpy="0 0 0" />
      <geometry>
        <mesh
          filename="./meshes/right_thumb_tactile0.STL" />
      </geometry>
      <material
        name="">
        <color
          rgba="0.61176 0.65882 0.67059 1" />
      </material>
    </visual>
    <collision>
      <origin
        xyz="0 0 0"
        rpy="0 0 0" />
      <geometry>
        <mesh
          filename="./meshes/right_thumb_tactile0.STL" />
      </geometry>
    </collision>
  </link>
  <joint
    name="right_thumb_tactile0_fix"
    type="fixed">
    <origin
      xyz="0 0 0"
      rpy="0 0 0" />
    <parent
      link="right_thumb_link2" />
    <child
      link="right_thumb_tactile0" />
    <axis
      xyz="0 0 0" />
  </joint>
  <link
    name="right_index_link0">
    <inertial>
      <origin
        xyz="0.005906 5.0422E-09 2.805E-05"
        rpy="0 0 0" />
      <mass
        value="0.018794" />
      <inertia
        ixx="3.0103E-07"
        ixy="2.7475E-13"
        ixz="1.0121E-09"
        iyy="7.5032E-07"
        iyz="-3.5706E-13"
        izz="6.574E-07" />
    </inertial>
    <visual>
      <origin
        xyz="0 0 0"
        rpy="0 0 0" />
      <geometry>
        <mesh
          filename="./meshes/right_index_link0.STL" />
      </geometry>
      <material
        name="">
        <color
          rgba="0.61176 0.65882 0.67059 1" />
      </material>
    </visual>
    <collision>
      <origin
        xyz="0 0 0"
        rpy="0 0 0" />
      <geometry>
        <mesh
          filename="./meshes/right_index_link0.STL" />
      </geometry>
    </collision>
  </link>
  <joint
    name="right_index_j0"
    type="revolute">
    <origin
      xyz="0.0071 0.034496 0.1188"
      rpy="0 -1.5708 0" />
    <parent
      link="right_palm_base" />
    <child
      link="right_index_link0" />
    <axis
      xyz="0 0 1" />
    <limit
      lower="-0.4363"
      upper="0.4363"
      effort="0"
      velocity="0" />
  </joint>
  <link
    name="right_index_link1">
    <inertial>
      <origin
        xyz="0.018577 -0.0016023 -3.9853E-06"
        rpy="0 0 0" />
      <mass
        value="0.029095" />
      <inertia
        ixx="6.585E-07"
        ixy="7.3586E-08"
        ixz="3.1705E-11"
        iyy="3.819E-06"
        iyz="-2.9734E-11"
        izz="3.7062E-06" />
    </inertial>
    <visual>
      <origin
        xyz="0 0 0"
        rpy="0 0 0" />
      <geometry>
        <mesh
          filename="./meshes/right_index_link1.STL" />
      </geometry>
      <material
        name="">
        <color
          rgba="0.61176 0.65882 0.67059 1" />
      </material>
    </visual>
    <collision>
      <origin
        xyz="0 0 0"
        rpy="0 0 0" />
      <geometry>
        <mesh
          filename="./meshes/right_index_link1.STL" />
      </geometry>
    </collision>
  </link>
  <joint
    name="right_index_j1"
    type="revolute">
    <origin
      xyz="0.016 0 0"
      rpy="-1.5708 0 0" />
    <parent
      link="right_index_link0" />
    <child
      link="right_index_link1" />
    <axis
      xyz="0 0 1" />
    <limit
      lower="-0.349"
      upper="1.5707"
      effort="0"
      velocity="0" />
  </joint>
  <link
    name="right_index_link2">
    <inertial>
      <origin
        xyz="0.012989 -0.0016282 5.019E-06"
        rpy="0 0 0" />
      <mass
        value="0.011142" />
      <inertia
        ixx="1.7953E-07"
        ixy="-6.8315E-09"
        ixz="1.7173E-11"
        iyy="5.5016E-07"
        iyz="2.3468E-10"
        izz="5.2493E-07" />
    </inertial>
    <visual>
      <origin
        xyz="0 0 0"
        rpy="0 0 0" />
      <geometry>
        <mesh
          filename="./meshes/right_index_link2.STL" />
      </geometry>
      <material
        name="">
        <color
          rgba="0.61176 0.65882 0.67059 1" />
      </material>
    </visual>
    <collision>
      <origin
        xyz="0 0 0"
        rpy="0 0 0" />
      <geometry>
        <mesh
          filename="./meshes/right_index_link2.STL" />
      </geometry>
    </collision>
  </link>
  <joint
    name="right_index_j2"
    type="revolute">
    <origin
      xyz="0.045 0 0"
      rpy="0 0 0" />
    <parent
      link="right_index_link1" />
    <child
      link="right_index_link2" />
    <axis
      xyz="0 0 1" />
    <limit
      lower="-0.0872"
      upper="1.7453"
      effort="0"
      velocity="0" />
  </joint>
  <link
    name="right_index_link3">
    <inertial>
      <origin
        xyz="0.010871 -0.001946 -3.2668E-06"
        rpy="0 0 0" />
      <mass
        value="0.005232" />
      <inertia
        ixx="7.2774E-08"
        ixy="9.8406E-09"
        ixz="-3.0061E-12"
        iyy="2.123E-07"
        iyz="4.5347E-12"
        izz="1.9117E-07" />
    </inertial>
    <visual>
      <origin
        xyz="0 0 0"
        rpy="0 0 0" />
      <geometry>
        <mesh
          filename="./meshes/right_index_link3.STL" />
      </geometry>
      <material
        name="">
        <color
          rgba="0.61176 0.65882 0.67059 1" />
      </material>
    </visual>
    <collision>
      <origin
        xyz="0 0 0"
        rpy="0 0 0" />
      <geometry>
        <mesh
          filename="./meshes/right_index_link3.STL" />
      </geometry>
    </collision>
  </link>
  <joint
    name="right_index_j3"
    type="revolute">
    <origin
      xyz="0.025 0 0"
      rpy="0 0 0" />
    <parent
      link="right_index_link2" />
    <child
      link="right_index_link3" />
    <axis
      xyz="0 0 1" />
    <limit
      lower="-0.0872"
      upper="1.7453"
      effort="0"
      velocity="0" />
    <mimic joint="right_index_j2" multiplier="1.0" offset="0"/>
  </joint>
  <link
    name="right_index_tactile2">
    <inertial>
      <origin
        xyz="0.016714 0.0032772 -3.1469E-06"
        rpy="0 0 0" />
      <mass
        value="0.009866" />
      <inertia
        ixx="3.5906E-08"
        ixy="5.8872E-09"
        ixz="-5.9576E-12"
        iyy="6.9849E-08"
        iyz="1.3184E-12"
        izz="4.887E-08" />
    </inertial>
    <visual>
      <origin
        xyz="0 0 0"
        rpy="0 0 0" />
      <geometry>
        <mesh
          filename="./meshes/right_index_tactile2.STL" />
      </geometry>
      <material
        name="">
        <color
          rgba="0.61176 0.65882 0.67059 1" />
      </material>
    </visual>
    <collision>
      <origin
        xyz="0 0 0"
        rpy="0 0 0" />
      <geometry>
        <mesh
          filename="./meshes/right_index_tactile2.STL" />
      </geometry>
    </collision>
  </link>
  <joint
    name="right_index_tactile2_fix"
    type="fixed">
    <origin
      xyz="0 0 0"
      rpy="0 0 0" />
    <parent
      link="right_index_link3" />
    <child
      link="right_index_tactile2" />
    <axis
      xyz="0 0 0" />
  </joint>
  <link
    name="right_index_pad">
    <inertial>
      <origin
        xyz="0 -1.73472347597681E-18 -3.63321957277257E-06"
        rpy="0 0 0" />
      <mass
        value="7.85398163397449E-07" />
      <inertia
        ixx="1.14537232162128E-13"
        ixy="-8.96831017167883E-44"
        ixz="-5.71292298138308E-29"
        iyy="1.14537232162128E-13"
        iyz="1.99711649026312E-43"
        izz="9.81747704246811E-14" />
    </inertial>
    <visual>
      <origin
        xyz="0 0 0"
        rpy="0 0 0" />
      <geometry>
        <mesh
          filename="./meshes/right_index_pad.STL" />
      </geometry>
      <material
        name="">
        <color
          rgba="1 0.6 0 1" />
      </material>
    </visual>
    <collision>
      <origin
        xyz="0 0 0"
        rpy="0 0 0" />
      <geometry>
        <mesh
          filename="./meshes/right_index_pad.STL" />
      </geometry>
    </collision>
  </link>
  <joint
    name="right_index_pad_fix"
    type="fixed">
    <origin
      xyz="0.017096 0.0071955 0"
      rpy="0 0 0" />
    <parent
      link="right_index_tactile2" />
    <child
      link="right_index_pad" />
    <axis
      xyz="0 0 0" />
  </joint>
  <link
    name="right_index_tip">
    <inertial>
      <origin
        xyz="-2.77555756156289E-17 0 -3.63321957280033E-06"
        rpy="0 0 0" />
      <mass
        value="9.81747704246811E-08" />
      <inertia
        ixx="3.5792885050665E-15"
        ixy="-4.20389539297445E-45"
        ixz="-1.78528843168221E-30"
        iyy="3.5792885050665E-15"
        iyz="6.58310291496404E-45"
        izz="3.06796157577129E-15" />
    </inertial>
    <visual>
      <origin
        xyz="0 0 0"
        rpy="0 0 0" />
      <geometry>
        <mesh
          filename="./meshes/right_index_tip.STL" />
      </geometry>
      <material
        name="">
        <color
          rgba="1 0.6 0 1" />
      </material>
    </visual>
    <collision>
      <origin
        xyz="0 0 0"
        rpy="0 0 0" />
      <geometry>
        <mesh
          filename="./meshes/right_index_tip.STL" />
      </geometry>
    </collision>
  </link>
  <joint
    name="right_index_tip_fix"
    type="fixed">
    <origin
      xyz="0.027672 0.00055028 0"
      rpy="0 0 0" />
    <parent
      link="right_index_tactile2" />
    <child
      link="right_index_tip" />
    <axis
      xyz="0 0 0" />
  </joint>
  <link
    name="right_index_tactile1">
    <inertial>
      <origin
        xyz="0.013244 0.0043138 -7.1146E-05"
        rpy="0 0 0" />
      <mass
        value="0.003635" />
      <inertia
        ixx="2.0761E-08"
        ixy="-4.7686E-10"
        ixz="-1.8249E-11"
        iyy="2.2921E-08"
        iyz="-2.6514E-11"
        izz="7.4089E-09" />
    </inertial>
    <visual>
      <origin
        xyz="0 0 0"
        rpy="0 0 0" />
      <geometry>
        <mesh
          filename="./meshes/right_index_tactile1.STL" />
      </geometry>
      <material
        name="">
        <color
          rgba="0.61176 0.65882 0.67059 1" />
      </material>
    </visual>
    <collision>
      <origin
        xyz="0 0 0"
        rpy="0 0 0" />
      <geometry>
        <mesh
          filename="./meshes/right_index_tactile1.STL" />
      </geometry>
    </collision>
  </link>
  <joint
    name="right_index_tactile1_fix"
    type="fixed">
    <origin
      xyz="0 0 0"
      rpy="0 0 0" />
    <parent
      link="right_index_link2" />
    <child
      link="right_index_tactile1" />
    <axis
      xyz="0 0 0" />
  </joint>
  <link
    name="right_index_tactile0">
    <inertial>
      <origin
        xyz="0.023088 0.0062078 -4.9139E-06"
        rpy="0 0 0" />
      <mass
        value="0.008926" />
      <inertia
        ixx="6.8465E-08"
        ixy="4.7902E-09"
        ixz="-1.0861E-11"
        iyy="1.3755E-07"
        iyz="-8.6995E-12"
        izz="9.8871E-08" />
    </inertial>
    <visual>
      <origin
        xyz="0 0 0"
        rpy="0 0 0" />
      <geometry>
        <mesh
          filename="./meshes/right_index_tactile0.STL" />
      </geometry>
      <material
        name="">
        <color
          rgba="0.61176 0.65882 0.67059 1" />
      </material>
    </visual>
    <collision>
      <origin
        xyz="0 0 0"
        rpy="0 0 0" />
      <geometry>
        <mesh
          filename="./meshes/right_index_tactile0.STL" />
      </geometry>
    </collision>
  </link>
  <joint
    name="right_index_tactile0_fix"
    type="fixed">
    <origin
      xyz="0 0 0"
      rpy="0 0 0" />
    <parent
      link="right_index_link1" />
    <child
      link="right_index_tactile0" />
    <axis
      xyz="0 0 0" />
  </joint>
  <link
    name="right_middle_link0">
    <inertial>
      <origin
        xyz="0.005906 5.0422E-09 2.805E-05"
        rpy="0 0 0" />
      <mass
        value="0.018794" />
      <inertia
        ixx="3.0103E-07"
        ixy="2.7475E-13"
        ixz="1.0121E-09"
        iyy="7.5032E-07"
        iyz="-3.5706E-13"
        izz="6.574E-07" />
    </inertial>
    <visual>
      <origin
        xyz="0 0 0"
        rpy="0 0 0" />
      <geometry>
        <mesh
          filename="./meshes/right_middle_link0.STL" />
      </geometry>
      <material
        name="">
        <color
          rgba="0.61176 0.65882 0.67059 1" />
      </material>
    </visual>
    <collision>
      <origin
        xyz="0 0 0"
        rpy="0 0 0" />
      <geometry>
        <mesh
          filename="./meshes/right_middle_link0.STL" />
      </geometry>
    </collision>
  </link>
  <joint
    name="right_middle_j0"
    type="revolute">
    <origin
      xyz="0.0071 0.011496 0.1218"
      rpy="0 -1.5708 0" />
    <parent
      link="right_palm_base" />
    <child
      link="right_middle_link0" />
    <axis
      xyz="0 0 1" />
    <limit
      lower="-0.4363"
      upper="0.4363"
      effort="0"
      velocity="0" />
  </joint>
  <link
    name="right_middle_link1">
    <inertial>
      <origin
        xyz="0.018577 -0.0016023 -3.9853E-06"
        rpy="0 0 0" />
      <mass
        value="0.029095" />
      <inertia
        ixx="6.585E-07"
        ixy="7.3586E-08"
        ixz="3.1705E-11"
        iyy="3.819E-06"
        iyz="-2.9734E-11"
        izz="3.7062E-06" />
    </inertial>
    <visual>
      <origin
        xyz="0 0 0"
        rpy="0 0 0" />
      <geometry>
        <mesh
          filename="./meshes/right_middle_link1.STL" />
      </geometry>
      <material
        name="">
        <color
          rgba="0.61176 0.65882 0.67059 1" />
      </material>
    </visual>
    <collision>
      <origin
        xyz="0 0 0"
        rpy="0 0 0" />
      <geometry>
        <mesh
          filename="./meshes/right_middle_link1.STL" />
      </geometry>
    </collision>
  </link>
  <joint
    name="right_middle_j1"
    type="revolute">
    <origin
      xyz="0.016 0 0"
      rpy="-1.5708 0 0" />
    <parent
      link="right_middle_link0" />
    <child
      link="right_middle_link1" />
    <axis
      xyz="0 0 1" />
    <limit
      lower="-0.349"
      upper="1.5707"
      effort="0"
      velocity="0" />
  </joint>
  <link
    name="right_middle_link2">
    <inertial>
      <origin
        xyz="0.012989 -0.0016282 5.019E-06"
        rpy="0 0 0" />
      <mass
        value="0.011142" />
      <inertia
        ixx="1.7953E-07"
        ixy="-6.8315E-09"
        ixz="1.7173E-11"
        iyy="5.5016E-07"
        iyz="2.3468E-10"
        izz="5.2493E-07" />
    </inertial>
    <visual>
      <origin
        xyz="0 0 0"
        rpy="0 0 0" />
      <geometry>
        <mesh
          filename="./meshes/right_middle_link2.STL" />
      </geometry>
      <material
        name="">
        <color
          rgba="0.61176 0.65882 0.67059 1" />
      </material>
    </visual>
    <collision>
      <origin
        xyz="0 0 0"
        rpy="0 0 0" />
      <geometry>
        <mesh
          filename="./meshes/right_middle_link2.STL" />
      </geometry>
    </collision>
  </link>
  <joint
    name="right_middle_j2"
    type="revolute">
    <origin
      xyz="0.045 0 0"
      rpy="0 0 0" />
    <parent
      link="right_middle_link1" />
    <child
      link="right_middle_link2" />
    <axis
      xyz="0 0 1" />
    <limit
      lower="-0.0872"
      upper="1.7453"
      effort="0"
      velocity="0" />
  </joint>
  <link
    name="right_middle_link3">
    <inertial>
      <origin
        xyz="0.010871 -0.001946 -3.2668E-06"
        rpy="0 0 0" />
      <mass
        value="0.005232" />
      <inertia
        ixx="7.2774E-08"
        ixy="9.8406E-09"
        ixz="-3.0061E-12"
        iyy="2.123E-07"
        iyz="4.5347E-12"
        izz="1.9117E-07" />
    </inertial>
    <visual>
      <origin
        xyz="0 0 0"
        rpy="0 0 0" />
      <geometry>
        <mesh
          filename="./meshes/right_middle_link3.STL" />
      </geometry>
      <material
        name="">
        <color
          rgba="0.61176 0.65882 0.67059 1" />
      </material>
    </visual>
    <collision>
      <origin
        xyz="0 0 0"
        rpy="0 0 0" />
      <geometry>
        <mesh
          filename="./meshes/right_middle_link3.STL" />
      </geometry>
    </collision>
  </link>
  <joint
    name="right_middle_j3"
    type="revolute">
    <origin
      xyz="0.025 0 0"
      rpy="0 0 0" />
    <parent
      link="right_middle_link2" />
    <child
      link="right_middle_link3" />
    <axis
      xyz="0 0 1" />
    <limit
      lower="-0.0872"
      upper="1.7453"
      effort="0"
      velocity="0" />
    <mimic joint="right_middle_j2" multiplier="1.0" offset="0"/>
  </joint>
  <link
    name="right_middle_tactile2">
    <inertial>
      <origin
        xyz="0.016714 0.0032772 -3.1469E-06"
        rpy="0 0 0" />
      <mass
        value="0.009866" />
      <inertia
        ixx="3.5906E-08"
        ixy="5.8872E-09"
        ixz="-5.9576E-12"
        iyy="6.9849E-08"
        iyz="1.3184E-12"
        izz="4.887E-08" />
    </inertial>
    <visual>
      <origin
        xyz="0 0 0"
        rpy="0 0 0" />
      <geometry>
        <mesh
          filename="./meshes/right_middle_tactile2.STL" />
      </geometry>
      <material
        name="">
        <color
          rgba="0.61176 0.65882 0.67059 1" />
      </material>
    </visual>
    <collision>
      <origin
        xyz="0 0 0"
        rpy="0 0 0" />
      <geometry>
        <mesh
          filename="./meshes/right_middle_tactile2.STL" />
      </geometry>
    </collision>
  </link>
  <joint
    name="right_middle_tactile2_fix"
    type="fixed">
    <origin
      xyz="0 0 0"
      rpy="0 0 0" />
    <parent
      link="right_middle_link3" />
    <child
      link="right_middle_tactile2" />
    <axis
      xyz="0 0 0" />
  </joint>
  <link
    name="right_middle_pad">
    <inertial>
      <origin
        xyz="2.77555756156289E-17 1.73472347597681E-18 -3.63321957278298E-06"
        rpy="0 0 0" />
      <mass
        value="7.85398163397448E-07" />
      <inertia
        ixx="1.14537232162128E-13"
        ixy="0"
        ixz="-6.0495036342773E-29"
        iyy="1.14537232162128E-13"
        iyz="2.0998736112379E-43"
        izz="9.81747704246809E-14" />
    </inertial>
    <visual>
      <origin
        xyz="0 0 0"
        rpy="0 0 0" />
      <geometry>
        <mesh
          filename="./meshes/right_middle_pad.STL" />
      </geometry>
      <material
        name="">
        <color
          rgba="1 0.6 0 1" />
      </material>
    </visual>
    <collision>
      <origin
        xyz="0 0 0"
        rpy="0 0 0" />
      <geometry>
        <mesh
          filename="./meshes/right_middle_pad.STL" />
      </geometry>
    </collision>
  </link>
  <joint
    name="right_middle_pad_fix"
    type="fixed">
    <origin
      xyz="0.017096144759137 0.00719554486026074 0"
      rpy="0 0 0" />
    <parent
      link="right_middle_tactile2" />
    <child
      link="right_middle_pad" />
    <axis
      xyz="0 0 0" />
  </joint>
  <link
    name="right_middle_tip">
    <inertial>
      <origin
        xyz="2.77555756156289E-17 1.73472347597681E-18 -3.633219572809E-06"
        rpy="0 0 0" />
      <mass
        value="9.81747704246811E-08" />
      <inertia
        ixx="3.5792885050665E-15"
        ixy="-4.20389539297445E-45"
        ixz="-1.78528843168221E-30"
        iyy="3.5792885050665E-15"
        iyz="6.58310291496404E-45"
        izz="3.06796157577129E-15" />
    </inertial>
    <visual>
      <origin
        xyz="0 0 0"
        rpy="0 0 0" />
      <geometry>
        <mesh
          filename="./meshes/right_middle_tip.STL" />
      </geometry>
      <material
        name="">
        <color
          rgba="1 0.6 0 1" />
      </material>
    </visual>
    <collision>
      <origin
        xyz="0 0 0"
        rpy="0 0 0" />
      <geometry>
        <mesh
          filename="./meshes/right_middle_tip.STL" />
      </geometry>
    </collision>
  </link>
  <joint
    name="right_middle_tip_fix"
    type="fixed">
    <origin
      xyz="0.027672166719793 0.000550277924150981 0"
      rpy="0 0 0" />
    <parent
      link="right_middle_tactile2" />
    <child
      link="right_middle_tip" />
    <axis
      xyz="0 0 0" />
  </joint>
  <link
    name="right_middle_tactile1">
    <inertial>
      <origin
        xyz="0.013244 0.0043138 -7.1146E-05"
        rpy="0 0 0" />
      <mass
        value="0.003635" />
      <inertia
        ixx="2.0761E-08"
        ixy="-4.7686E-10"
        ixz="-1.8249E-11"
        iyy="2.2921E-08"
        iyz="-2.6514E-11"
        izz="7.4089E-09" />
    </inertial>
    <visual>
      <origin
        xyz="0 0 0"
        rpy="0 0 0" />
      <geometry>
        <mesh
          filename="./meshes/right_middle_tactile1.STL" />
      </geometry>
      <material
        name="">
        <color
          rgba="0.61176 0.65882 0.67059 1" />
      </material>
    </visual>
    <collision>
      <origin
        xyz="0 0 0"
        rpy="0 0 0" />
      <geometry>
        <mesh
          filename="./meshes/right_middle_tactile1.STL" />
      </geometry>
    </collision>
  </link>
  <joint
    name="right_middle_tactile1_fix"
    type="fixed">
    <origin
      xyz="0 0 0"
      rpy="0 0 0" />
    <parent
      link="right_middle_link2" />
    <child
      link="right_middle_tactile1" />
    <axis
      xyz="0 0 0" />
  </joint>
  <link
    name="right_middle_tactile0">
    <inertial>
      <origin
        xyz="0.023088 0.0062078 -4.9139E-06"
        rpy="0 0 0" />
      <mass
        value="0.008926" />
      <inertia
        ixx="6.8465E-08"
        ixy="4.7902E-09"
        ixz="-1.0861E-11"
        iyy="1.3755E-07"
        iyz="-8.6995E-12"
        izz="9.8871E-08" />
    </inertial>
    <visual>
      <origin
        xyz="0 0 0"
        rpy="0 0 0" />
      <geometry>
        <mesh
          filename="./meshes/right_middle_tactile0.STL" />
      </geometry>
      <material
        name="">
        <color
          rgba="0.61176 0.65882 0.67059 1" />
      </material>
    </visual>
    <collision>
      <origin
        xyz="0 0 0"
        rpy="0 0 0" />
      <geometry>
        <mesh
          filename="./meshes/right_middle_tactile0.STL" />
      </geometry>
    </collision>
  </link>
  <joint
    name="right_middle_tactile0_fix"
    type="fixed">
    <origin
      xyz="0 0 0"
      rpy="0 0 0" />
    <parent
      link="right_middle_link1" />
    <child
      link="right_middle_tactile0" />
    <axis
      xyz="0 0 0" />
  </joint>
  <link
    name="right_ring_link0">
    <inertial>
      <origin
        xyz="0.005906 5.0422E-09 2.805E-05"
        rpy="0 0 0" />
      <mass
        value="0.018794" />
      <inertia
        ixx="3.0103E-07"
        ixy="2.7475E-13"
        ixz="1.0121E-09"
        iyy="7.5032E-07"
        iyz="-3.5706E-13"
        izz="6.574E-07" />
    </inertial>
    <visual>
      <origin
        xyz="0 0 0"
        rpy="0 0 0" />
      <geometry>
        <mesh
          filename="./meshes/right_ring_link0.STL" />
      </geometry>
      <material
        name="">
        <color
          rgba="0.61176 0.65882 0.67059 1" />
      </material>
    </visual>
    <collision>
      <origin
        xyz="0 0 0"
        rpy="0 0 0" />
      <geometry>
        <mesh
          filename="./meshes/right_ring_link0.STL" />
      </geometry>
    </collision>
  </link>
  <joint
    name="right_ring_j0"
    type="revolute">
    <origin
      xyz="0.0071 -0.011503 0.1188"
      rpy="0 -1.5708 0" />
    <parent
      link="right_palm_base" />
    <child
      link="right_ring_link0" />
    <axis
      xyz="0 0 1" />
    <limit
      lower="-0.4363"
      upper="0.4363"
      effort="0"
      velocity="0" />
  </joint>
  <link
    name="right_ring_link1">
    <inertial>
      <origin
        xyz="0.018577 -0.0016023 -3.9853E-06"
        rpy="0 0 0" />
      <mass
        value="0.029095" />
      <inertia
        ixx="6.585E-07"
        ixy="7.3586E-08"
        ixz="3.1705E-11"
        iyy="3.819E-06"
        iyz="-2.9734E-11"
        izz="3.7062E-06" />
    </inertial>
    <visual>
      <origin
        xyz="0 0 0"
        rpy="0 0 0" />
      <geometry>
        <mesh
          filename="./meshes/right_ring_link1.STL" />
      </geometry>
      <material
        name="">
        <color
          rgba="0.61176 0.65882 0.67059 1" />
      </material>
    </visual>
    <collision>
      <origin
        xyz="0 0 0"
        rpy="0 0 0" />
      <geometry>
        <mesh
          filename="./meshes/right_ring_link1.STL" />
      </geometry>
    </collision>
  </link>
  <joint
    name="right_ring_j1"
    type="revolute">
    <origin
      xyz="0.016 0 0"
      rpy="-1.5708 0 0" />
    <parent
      link="right_ring_link0" />
    <child
      link="right_ring_link1" />
    <axis
      xyz="0 0 1" />
    <limit
      lower="-0.349"
      upper="1.5707"
      effort="0"
      velocity="0" />
  </joint>
  <link
    name="right_ring_link2">
    <inertial>
      <origin
        xyz="0.012989 -0.0016282 5.019E-06"
        rpy="0 0 0" />
      <mass
        value="0.011142" />
      <inertia
        ixx="1.7953E-07"
        ixy="-6.8315E-09"
        ixz="1.7173E-11"
        iyy="5.5016E-07"
        iyz="2.3468E-10"
        izz="5.2493E-07" />
    </inertial>
    <visual>
      <origin
        xyz="0 0 0"
        rpy="0 0 0" />
      <geometry>
        <mesh
          filename="./meshes/right_ring_link2.STL" />
      </geometry>
      <material
        name="">
        <color
          rgba="0.61176 0.65882 0.67059 1" />
      </material>
    </visual>
    <collision>
      <origin
        xyz="0 0 0"
        rpy="0 0 0" />
      <geometry>
        <mesh
          filename="./meshes/right_ring_link2.STL" />
      </geometry>
    </collision>
  </link>
  <joint
    name="right_ring_j2"
    type="revolute">
    <origin
      xyz="0.045 0 0"
      rpy="0 0 0" />
    <parent
      link="right_ring_link1" />
    <child
      link="right_ring_link2" />
    <axis
      xyz="0 0 1" />
    <limit
      lower="-0.0872"
      upper="1.7453"
      effort="0"
      velocity="0" />
  </joint>
  <link
    name="right_ring_link3">
    <inertial>
      <origin
        xyz="0.010871 -0.001946 -3.2668E-06"
        rpy="0 0 0" />
      <mass
        value="0.005232" />
      <inertia
        ixx="7.2774E-08"
        ixy="9.8406E-09"
        ixz="-3.0061E-12"
        iyy="2.123E-07"
        iyz="4.5347E-12"
        izz="1.9117E-07" />
    </inertial>
    <visual>
      <origin
        xyz="0 0 0"
        rpy="0 0 0" />
      <geometry>
        <mesh
          filename="./meshes/right_ring_link3.STL" />
      </geometry>
      <material
        name="">
        <color
          rgba="0.61176 0.65882 0.67059 1" />
      </material>
    </visual>
    <collision>
      <origin
        xyz="0 0 0"
        rpy="0 0 0" />
      <geometry>
        <mesh
          filename="./meshes/right_ring_link3.STL" />
      </geometry>
    </collision>
  </link>
  <joint
    name="right_ring_j3"
    type="revolute">
    <origin
      xyz="0.025 0 0"
      rpy="0 0 0" />
    <parent
      link="right_ring_link2" />
    <child
      link="right_ring_link3" />
    <axis
      xyz="0 0 1" />
    <limit
      lower="-0.0872"
      upper="1.7453"
      effort="0"
      velocity="0" />
    <mimic joint="right_ring_j2" multiplier="1.0" offset="0"/>
  </joint>
  <link
    name="right_ring_tactile2">
    <inertial>
      <origin
        xyz="0.016714 0.0032772 -3.1469E-06"
        rpy="0 0 0" />
      <mass
        value="0.009866" />
      <inertia
        ixx="3.5906E-08"
        ixy="5.8872E-09"
        ixz="-5.9576E-12"
        iyy="6.9849E-08"
        iyz="1.3184E-12"
        izz="4.887E-08" />
    </inertial>
    <visual>
      <origin
        xyz="0 0 0"
        rpy="0 0 0" />
      <geometry>
        <mesh
          filename="./meshes/right_ring_tactile2.STL" />
      </geometry>
      <material
        name="">
        <color
          rgba="0.61176 0.65882 0.67059 1" />
      </material>
    </visual>
    <collision>
      <origin
        xyz="0 0 0"
        rpy="0 0 0" />
      <geometry>
        <mesh
          filename="./meshes/right_ring_tactile2.STL" />
      </geometry>
    </collision>
  </link>
  <joint
    name="right_ring_tactile2_fix"
    type="fixed">
    <origin
      xyz="0 0 0"
      rpy="0 0 0" />
    <parent
      link="right_ring_link3" />
    <child
      link="right_ring_tactile2" />
    <axis
      xyz="0 0 0" />
  </joint>
  <link
    name="right_ring_pad">
    <inertial>
      <origin
        xyz="-2.77555756156289E-17 0 -3.63321957278992E-06"
        rpy="0 0 0" />
      <mass
        value="7.85398163397448E-07" />
      <inertia
        ixx="1.14537232162128E-13"
        ixy="0"
        ixz="-6.0495036342773E-29"
        iyy="1.14537232162128E-13"
        iyz="2.0998736112379E-43"
        izz="9.81747704246809E-14" />
    </inertial>
    <visual>
      <origin
        xyz="0 0 0"
        rpy="0 0 0" />
      <geometry>
        <mesh
          filename="./meshes/right_ring_pad.STL" />
      </geometry>
      <material
        name="">
        <color
          rgba="1 0.6 0 1" />
      </material>
    </visual>
    <collision>
      <origin
        xyz="0 0 0"
        rpy="0 0 0" />
      <geometry>
        <mesh
          filename="./meshes/right_ring_pad.STL" />
      </geometry>
    </collision>
  </link>
  <joint
    name="right_ring_pad_fix"
    type="fixed">
    <origin
      xyz="0.017096144759137 0.00719554486026074 0"
      rpy="0 0 0" />
    <parent
      link="right_ring_tactile2" />
    <child
      link="right_ring_pad" />
    <axis
      xyz="0 0 0" />
  </joint>
  <link
    name="right_ring_tip">
    <inertial>
      <origin
        xyz="0 -8.67361737988404E-19 -3.63321957278992E-06"
        rpy="0 0 0" />
      <mass
        value="9.81747704246808E-08" />
      <inertia
        ixx="3.57928850506648E-15"
        ixy="-1.40129846432482E-45"
        ixz="-1.89046988571163E-30"
        iyy="3.57928850506648E-15"
        iyz="6.86962751972205E-45"
        izz="3.06796157577127E-15" />
    </inertial>
    <visual>
      <origin
        xyz="0 0 0"
        rpy="0 0 0" />
      <geometry>
        <mesh
          filename="./meshes/right_ring_tip.STL" />
      </geometry>
      <material
        name="">
        <color
          rgba="1 0.6 0 1" />
      </material>
    </visual>
    <collision>
      <origin
        xyz="0 0 0"
        rpy="0 0 0" />
      <geometry>
        <mesh
          filename="./meshes/right_ring_tip.STL" />
      </geometry>
    </collision>
  </link>
  <joint
    name="right_ring_tip_fix"
    type="fixed">
    <origin
      xyz="0.027672166719793 0.000550277924150982 0"
      rpy="0 0 0" />
    <parent
      link="right_ring_tactile2" />
    <child
      link="right_ring_tip" />
    <axis
      xyz="0 0 0" />
  </joint>
  <link
    name="right_ring_tactile1">
    <inertial>
      <origin
        xyz="0.013244 0.0043138 -7.1146E-05"
        rpy="0 0 0" />
      <mass
        value="0.003635" />
      <inertia
        ixx="2.0761E-08"
        ixy="-4.7686E-10"
        ixz="-1.8249E-11"
        iyy="2.2921E-08"
        iyz="-2.6514E-11"
        izz="7.4089E-09" />
    </inertial>
    <visual>
      <origin
        xyz="0 0 0"
        rpy="0 0 0" />
      <geometry>
        <mesh
          filename="./meshes/right_ring_tactile1.STL" />
      </geometry>
      <material
        name="">
        <color
          rgba="0.61176 0.65882 0.67059 1" />
      </material>
    </visual>
    <collision>
      <origin
        xyz="0 0 0"
        rpy="0 0 0" />
      <geometry>
        <mesh
          filename="./meshes/right_ring_tactile1.STL" />
      </geometry>
    </collision>
  </link>
  <joint
    name="right_ring_tactile1_fix"
    type="fixed">
    <origin
      xyz="0 0 0"
      rpy="0 0 0" />
    <parent
      link="right_ring_link2" />
    <child
      link="right_ring_tactile1" />
    <axis
      xyz="0 0 0" />
  </joint>
  <link
    name="right_ring_tactile0">
    <inertial>
      <origin
        xyz="0.023088 0.0062078 -4.9139E-06"
        rpy="0 0 0" />
      <mass
        value="0.008926" />
      <inertia
        ixx="6.8465E-08"
        ixy="4.7902E-09"
        ixz="-1.0861E-11"
        iyy="1.3755E-07"
        iyz="-8.6995E-12"
        izz="9.8871E-08" />
    </inertial>
    <visual>
      <origin
        xyz="0 0 0"
        rpy="0 0 0" />
      <geometry>
        <mesh
          filename="./meshes/right_ring_tactile0.STL" />
      </geometry>
      <material
        name="">
        <color
          rgba="0.61176 0.65882 0.67059 1" />
      </material>
    </visual>
    <collision>
      <origin
        xyz="0 0 0"
        rpy="0 0 0" />
      <geometry>
        <mesh
          filename="./meshes/right_ring_tactile0.STL" />
      </geometry>
    </collision>
  </link>
  <joint
    name="right_ring_tactile0_fix"
    type="fixed">
    <origin
      xyz="0 0 0"
      rpy="0 0 0" />
    <parent
      link="right_ring_link1" />
    <child
      link="right_ring_tactile0" />
    <axis
      xyz="0 0 0" />
  </joint>
  <link
    name="right_pinky_link0">
    <inertial>
      <origin
        xyz="0.005906 5.0422E-09 2.805E-05"
        rpy="0 0 0" />
      <mass
        value="0.018794" />
      <inertia
        ixx="3.0103E-07"
        ixy="2.7475E-13"
        ixz="1.0121E-09"
        iyy="7.5032E-07"
        iyz="-3.5706E-13"
        izz="6.574E-07" />
    </inertial>
    <visual>
      <origin
        xyz="0 0 0"
        rpy="0 0 0" />
      <geometry>
        <mesh
          filename="./meshes/right_pinky_link0.STL" />
      </geometry>
      <material
        name="">
        <color
          rgba="0.61176 0.65882 0.67059 1" />
      </material>
    </visual>
    <collision>
      <origin
        xyz="0 0 0"
        rpy="0 0 0" />
      <geometry>
        <mesh
          filename="./meshes/right_pinky_link0.STL" />
      </geometry>
    </collision>
  </link>
  <joint
    name="right_pinky_j0"
    type="revolute">
    <origin
      xyz="0.0071 -0.034504 0.1158"
      rpy="0 -1.5708 0" />
    <parent
      link="right_palm_base" />
    <child
      link="right_pinky_link0" />
    <axis
      xyz="0 0 1" />
    <limit
      lower="-0.4363"
      upper="0.4363"
      effort="0"
      velocity="0" />
  </joint>
  <link
    name="right_pinky_link1">
    <inertial>
      <origin
        xyz="0.018577 -0.0016023 -3.9853E-06"
        rpy="0 0 0" />
      <mass
        value="0.029095" />
      <inertia
        ixx="6.585E-07"
        ixy="7.3586E-08"
        ixz="3.1705E-11"
        iyy="3.819E-06"
        iyz="-2.9734E-11"
        izz="3.7062E-06" />
    </inertial>
    <visual>
      <origin
        xyz="0 0 0"
        rpy="0 0 0" />
      <geometry>
        <mesh
          filename="./meshes/right_pinky_link1.STL" />
      </geometry>
      <material
        name="">
        <color
          rgba="0.61176 0.65882 0.67059 1" />
      </material>
    </visual>
    <collision>
      <origin
        xyz="0 0 0"
        rpy="0 0 0" />
      <geometry>
        <mesh
          filename="./meshes/right_pinky_link1.STL" />
      </geometry>
    </collision>
  </link>
  <joint
    name="right_pinky_j1"
    type="revolute">
    <origin
      xyz="0.016 0 0"
      rpy="-1.5708 0 0" />
    <parent
      link="right_pinky_link0" />
    <child
      link="right_pinky_link1" />
    <axis
      xyz="0 0 1" />
    <limit
      lower="-0.349"
      upper="1.5707"
      effort="0"
      velocity="0" />
  </joint>
  <link
    name="right_pinky_link2">
    <inertial>
      <origin
        xyz="0.012989 -0.0016282 5.0179E-06"
        rpy="0 0 0" />
      <mass
        value="0.011142" />
      <inertia
        ixx="1.7953E-07"
        ixy="-6.8317E-09"
        ixz="1.7221E-11"
        iyy="5.5016E-07"
        iyz="2.3466E-10"
        izz="5.2493E-07" />
    </inertial>
    <visual>
      <origin
        xyz="0 0 0"
        rpy="0 0 0" />
      <geometry>
        <mesh
          filename="./meshes/right_pinky_link2.STL" />
      </geometry>
      <material
        name="">
        <color
          rgba="0.61176 0.65882 0.67059 1" />
      </material>
    </visual>
    <collision>
      <origin
        xyz="0 0 0"
        rpy="0 0 0" />
      <geometry>
        <mesh
          filename="./meshes/right_pinky_link2.STL" />
      </geometry>
    </collision>
  </link>
  <joint
    name="right_pinky_j2"
    type="revolute">
    <origin
      xyz="0.045 0 0"
      rpy="0 0 0" />
    <parent
      link="right_pinky_link1" />
    <child
      link="right_pinky_link2" />
    <axis
      xyz="0 0 1" />
    <limit
      lower="-0.0872"
      upper="1.7453"
      effort="0"
      velocity="0" />
  </joint>
  <link
    name="right_pinky_link3">
    <inertial>
      <origin
        xyz="0.010871 -0.001946 -3.2672E-06"
        rpy="0 0 0" />
      <mass
        value="0.005232" />
      <inertia
        ixx="7.2774E-08"
        ixy="9.8405E-09"
        ixz="-3.0153E-12"
        iyy="2.123E-07"
        iyz="4.5299E-12"
        izz="1.9117E-07" />
    </inertial>
    <visual>
      <origin
        xyz="0 0 0"
        rpy="0 0 0" />
      <geometry>
        <mesh
          filename="./meshes/right_pinky_link3.STL" />
      </geometry>
      <material
        name="">
        <color
          rgba="0.61176 0.65882 0.67059 1" />
      </material>
    </visual>
    <collision>
      <origin
        xyz="0 0 0"
        rpy="0 0 0" />
      <geometry>
        <mesh
          filename="./meshes/right_pinky_link3.STL" />
      </geometry>
    </collision>
  </link>
  <joint
    name="right_pinky_j3"
    type="revolute">
    <origin
      xyz="0.025 0 0"
      rpy="0 0 0" />
    <parent
      link="right_pinky_link2" />
    <child
      link="right_pinky_link3" />
    <axis
      xyz="0 0 1" />
    <limit
      lower="-0.0872"
      upper="1.7453"
      effort="0"
      velocity="0" />
    <mimic joint="right_pinky_j2" multiplier="1.0" offset="0"/>
  </joint>
  <link
    name="right_pinky_tactile2">
    <inertial>
      <origin
        xyz="0.016714 0.0032772 -3.1469E-06"
        rpy="0 0 0" />
      <mass
        value="0.009866" />
      <inertia
        ixx="3.5906E-08"
        ixy="5.8872E-09"
        ixz="-5.9576E-12"
        iyy="6.9849E-08"
        iyz="1.3184E-12"
        izz="4.887E-08" />
    </inertial>
    <visual>
      <origin
        xyz="0 0 0"
        rpy="0 0 0" />
      <geometry>
        <mesh
          filename="./meshes/right_pinky_tactile2.STL" />
      </geometry>
      <material
        name="">
        <color
          rgba="0.61176 0.65882 0.67059 1" />
      </material>
    </visual>
    <collision>
      <origin
        xyz="0 0 0"
        rpy="0 0 0" />
      <geometry>
        <mesh
          filename="./meshes/right_pinky_tactile2.STL" />
      </geometry>
    </collision>
  </link>
  <joint
    name="right_pinky_tactile2_fix"
    type="fixed">
    <origin
      xyz="0 0 0"
      rpy="0 0 0" />
    <parent
      link="right_pinky_link3" />
    <child
      link="right_pinky_tactile2" />
    <axis
      xyz="0 0 0" />
  </joint>
  <link
    name="right_pinky_pad">
    <inertial>
      <origin
        xyz="2.77555756156289E-17 1.73472347597681E-18 -3.63321957277951E-06"
        rpy="0 0 0" />
      <mass
        value="7.85398163397449E-07" />
      <inertia
        ixx="1.14537232162128E-13"
        ixy="-8.96831017167883E-44"
        ixz="-5.71292298138308E-29"
        iyy="1.14537232162128E-13"
        iyz="1.99711649026312E-43"
        izz="9.81747704246811E-14" />
    </inertial>
    <visual>
      <origin
        xyz="0 0 0"
        rpy="0 0 0" />
      <geometry>
        <mesh
          filename="./meshes/right_pinky_pad.STL" />
      </geometry>
      <material
        name="">
        <color
          rgba="1 0.6 0 1" />
      </material>
    </visual>
    <collision>
      <origin
        xyz="0 0 0"
        rpy="0 0 0" />
      <geometry>
        <mesh
          filename="./meshes/right_pinky_pad.STL" />
      </geometry>
    </collision>
  </link>
  <joint
    name="right_pinky_pad_fix"
    type="fixed">
    <origin
      xyz="0.017096 0.0071955 0"
      rpy="0 0 0" />
    <parent
      link="right_pinky_tactile2" />
    <child
      link="right_pinky_pad" />
    <axis
      xyz="0 0 0" />
  </joint>
  <link
    name="right_pinky_tip">
    <inertial>
      <origin
        xyz="0 0 -3.63321957280727E-06"
        rpy="0 0 0" />
      <mass
        value="9.81747704246811E-08" />
      <inertia
        ixx="3.5792885050665E-15"
        ixy="-4.20389539297445E-45"
        ixz="-1.78528843168221E-30"
        iyy="3.5792885050665E-15"
        iyz="6.58310291496404E-45"
        izz="3.06796157577129E-15" />
    </inertial>
    <visual>
      <origin
        xyz="0 0 0"
        rpy="0 0 0" />
      <geometry>
        <mesh
          filename="./meshes/right_pinky_tip.STL" />
      </geometry>
      <material
        name="">
        <color
          rgba="1 0.6 0 1" />
      </material>
    </visual>
    <collision>
      <origin
        xyz="0 0 0"
        rpy="0 0 0" />
      <geometry>
        <mesh
          filename="./meshes/right_pinky_tip.STL" />
      </geometry>
    </collision>
  </link>
  <joint
    name="right_pinky_tip_fix"
    type="fixed">
    <origin
      xyz="0.027672 0.00055028 0"
      rpy="0 0 0" />
    <parent
      link="right_pinky_tactile2" />
    <child
      link="right_pinky_tip" />
    <axis
      xyz="0 0 0" />
  </joint>
  <link
    name="right_pinky_tactile1">
    <inertial>
      <origin
        xyz="0.013244 0.0043138 -7.1146E-05"
        rpy="0 0 0" />
      <mass
        value="0.003635" />
      <inertia
        ixx="2.0761E-08"
        ixy="-4.7686E-10"
        ixz="-1.8249E-11"
        iyy="2.2921E-08"
        iyz="-2.6514E-11"
        izz="7.4089E-09" />
    </inertial>
    <visual>
      <origin
        xyz="0 0 0"
        rpy="0 0 0" />
      <geometry>
        <mesh
          filename="./meshes/right_pinky_tactile1.STL" />
      </geometry>
      <material
        name="">
        <color
          rgba="0.61176 0.65882 0.67059 1" />
      </material>
    </visual>
    <collision>
      <origin
        xyz="0 0 0"
        rpy="0 0 0" />
      <geometry>
        <mesh
          filename="./meshes/right_pinky_tactile1.STL" />
      </geometry>
    </collision>
  </link>
  <joint
    name="right_pinky_tactile1_fix"
    type="fixed">
    <origin
      xyz="0 0 0"
      rpy="0 0 0" />
    <parent
      link="right_pinky_link2" />
    <child
      link="right_pinky_tactile1" />
    <axis
      xyz="0 0 0" />
  </joint>
  <link
    name="right_pinky_tactile0">
    <inertial>
      <origin
        xyz="0.023088 0.0062078 -4.9139E-06"
        rpy="0 0 0" />
      <mass
        value="0.008926" />
      <inertia
        ixx="6.8465E-08"
        ixy="4.7902E-09"
        ixz="-1.0861E-11"
        iyy="1.3755E-07"
        iyz="-8.6995E-12"
        izz="9.8871E-08" />
    </inertial>
    <visual>
      <origin
        xyz="0 0 0"
        rpy="0 0 0" />
      <geometry>
        <mesh
          filename="./meshes/right_pinky_tactile0.STL" />
      </geometry>
      <material
        name="">
        <color
          rgba="0.61176 0.65882 0.67059 1" />
      </material>
    </visual>
    <collision>
      <origin
        xyz="0 0 0"
        rpy="0 0 0" />
      <geometry>
        <mesh
          filename="./meshes/right_pinky_tactile0.STL" />
      </geometry>
    </collision>
  </link>
  <joint
    name="right_pinky_tactile0_fix"
    type="fixed">
    <origin
      xyz="0 0 0"
      rpy="0 0 0" />
    <parent
      link="right_pinky_link1" />
    <child
      link="right_pinky_tactile0" />
    <axis
      xyz="0 0 0" />
  </joint>
  <link
    name="right_palm_tactile">
    <inertial>
      <origin
        xyz="0 0 0"
        rpy="0 0 0" />
      <mass
        value="0" />
      <inertia
        ixx="0"
        ixy="0"
        ixz="0"
        iyy="0"
        iyz="0"
        izz="0" />
    </inertial>
    <visual>
      <origin
        xyz="0 0 0"
        rpy="0 0 0" />
      <geometry>
        <mesh
          filename="./meshes/right_palm_tactile.STL" />
      </geometry>
      <material
        name="">
        <color
          rgba="0.61176 0.65882 0.67059 1" />
      </material>
    </visual>
    <collision>
      <origin
        xyz="0 0 0"
        rpy="0 0 0" />
      <geometry>
        <mesh
          filename="./meshes/right_palm_tactile.STL" />
      </geometry>
    </collision>
  </link>
  <joint
    name="right_palm_tactile_fix"
    type="fixed">
    <origin
      xyz="0 0 0"
      rpy="0 0 0" />
    <parent
      link="right_palm_link" />
    <child
      link="right_palm_tactile" />
    <axis
      xyz="0 0 0" />
  </joint>
</robot>
