<?xml version="1.0" encoding="utf-8"?>
<!-- This URDF was automatically created by SolidWorks to URDF Exporter! Originally created by Stephen Brawner (brawner@gmail.com) 
     Commit Version: 1.6.0-4-g7f85cfe  Build Version: 1.6.7995.38578
     For more information, please see http://wiki.ros.org/sw_urdf_exporter -->
<robot
  name="right_apex_hand">
  <link
    name="right_palm_link">
    <inertial>
      <origin
        xyz="-0.00293711171232502 0.000113307755926331 0.0646647515180297"
        rpy="0 0 0" />
      <mass
        value="0.262735816921321" />
      <inertia
        ixx="0.000341359715423482"
        ixy="3.9880062499101E-06"
        ixz="-5.62269002088488E-06"
        iyy="0.000220629487963476"
        iyz="5.26877977739229E-07"
        izz="0.000163733985955337" />
    </inertial>
    <visual>
      <origin
        xyz="0 0 0"
        rpy="0 0 0" />
      <geometry>
        <mesh
          filename="./meshes/right_palm_link.STL" />
      </geometry>
      <material
        name="">
        <color
          rgba="0.792156862745098 0.819607843137255 0.933333333333333 1" />
      </material>
    </visual>
    <collision>
      <origin
        xyz="0 0 0"
        rpy="0 0 0" />
      <geometry>
        <mesh
          filename="./meshes/right_palm_link.STL" />
      </geometry>
    </collision>
  </link>
  <link
    name="right_thumb_link_0">
    <inertial>
      <origin
        xyz="0.00743352291727649 -3.46944695195361E-18 0.00039433256296964"
        rpy="0 0 0" />
      <mass
        value="0.0109675846438251" />
      <inertia
        ixx="8.52941299389875E-07"
        ixy="2.71626717104376E-22"
        ixz="3.23200630925962E-08"
        iyy="7.59561550929961E-07"
        iyz="-1.18807970709975E-21"
        izz="6.03762145339431E-07" />
    </inertial>
    <visual>
      <origin
        xyz="0 0 0"
        rpy="0 0 0" />
      <geometry>
        <mesh
          filename="./meshes/right_thumb_link_0.STL" />
      </geometry>
      <material
        name="">
        <color
          rgba="0.792156862745098 0.819607843137255 0.933333333333333 1" />
      </material>
    </visual>
    <collision>
      <origin
        xyz="0 0 0"
        rpy="0 0 0" />
      <geometry>
        <mesh
          filename="./meshes/right_thumb_link_0.STL" />
      </geometry>
    </collision>
  </link>
  <joint
    name="right_thumb_j0"
    type="revolute">
    <origin
      xyz="0.012998 0.022996 0.0493"
      rpy="3.1416 0 1.5708" />
    <parent
      link="right_palm_link" />
    <child
      link="right_thumb_link_0" />
    <axis
      xyz="0 0 1" />
    <limit
      lower="0"
      upper="1.3963"
      effort="0"
      velocity="8.7266" />
  </joint>
  <link
    name="right_thumb_link_1">
    <inertial>
      <origin
        xyz="-2.48033218011433E-05 0 0.00847195900565391"
        rpy="0 0 0" />
      <mass
        value="0.015512035165475" />
      <inertia
        ixx="1.27793414896908E-06"
        ixy="1.04229820242801E-23"
        ixz="-2.29771122742565E-09"
        iyy="1.0808066678358E-06"
        iyz="1.50446424889577E-22"
        izz="7.13289303293697E-07" />
    </inertial>
    <visual>
      <origin
        xyz="0 0 0"
        rpy="0 0 0" />
      <geometry>
        <mesh
          filename="./meshes/right_thumb_link_1.STL" />
      </geometry>
      <material
        name="">
        <color
          rgba="0.792156862745098 0.819607843137255 0.933333333333333 1" />
      </material>
    </visual>
    <collision>
      <origin
        xyz="0 0 0"
        rpy="0 0 0" />
      <geometry>
        <mesh
          filename="./meshes/right_thumb_link_1.STL" />
      </geometry>
    </collision>
  </link>
  <joint
    name="right_thumb_j1"
    type="revolute">
    <origin
      xyz="0.0145 0 0"
      rpy="-1.5708 0 -1.5708" />
    <parent
      link="right_thumb_link_0" />
    <child
      link="right_thumb_link_1" />
    <axis
      xyz="0 0 1" />
    <limit
      lower="-0.1745"
      upper="1.047"
      effort="0"
      velocity="8.7266" />
  </joint>
  <link
    name="right_thumb_link_2">
    <inertial>
      <origin
        xyz="-0.00553826659447157 -0.0253626883037425 -0.000927978595093725"
        rpy="0 0 0" />
      <mass
        value="0.0478768695058164" />
      <inertia
        ixx="2.34858768591945E-05"
        ixy="1.71139425848764E-07"
        ixz="1.18120809874717E-07"
        iyy="4.59992053752202E-06"
        iyz="1.09660366729134E-06"
        izz="2.07515814865186E-05" />
    </inertial>
    <visual>
      <origin
        xyz="0 0 0"
        rpy="0 0 0" />
      <geometry>
        <mesh
          filename="./meshes/right_thumb_link_2.STL" />
      </geometry>
      <material
        name="">
        <color
          rgba="0.792156862745098 0.819607843137255 0.933333333333333 1" />
      </material>
    </visual>
    <collision>
      <origin
        xyz="0 0 0"
        rpy="0 0 0" />
      <geometry>
        <mesh
          filename="./meshes/right_thumb_link_2.STL" />
      </geometry>
    </collision>
  </link>
  <joint
    name="right_thumb_j2"
    type="revolute">
    <origin
      xyz="0 0 0.014"
      rpy="-1.5708 0 1.5708" />
    <parent
      link="right_thumb_link_1" />
    <child
      link="right_thumb_link_2" />
    <axis
      xyz="0 0 1" />
    <limit
      lower="0"
      upper="1.396"
      effort="0"
      velocity="8.7266" />
  </joint>
  <link
    name="right_thumb_tactile_0">
    <inertial>
      <origin
        xyz="-0.00373820569666419 -0.0269854303577748 -0.000760411010707918"
        rpy="0 0 0" />
      <mass
        value="0.0359955797573235" />
      <inertia
        ixx="8.21543370377076E-06"
        ixy="2.47385128317901E-07"
        ixz="-1.12170832224441E-07"
        iyy="4.86699087841771E-06"
        iyz="2.71797107980499E-07"
        izz="6.31282638693907E-06" />
    </inertial>
    <visual>
      <origin
        xyz="0 0 0"
        rpy="0 0 0" />
      <geometry>
        <mesh
          filename="./meshes/right_thumb_tactile_0.STL" />
      </geometry>
      <material
        name="">
        <color
          rgba="0.792156862745098 0.819607843137255 0.933333333333333 1" />
      </material>
    </visual>
    <collision>
      <origin
        xyz="0 0 0"
        rpy="0 0 0" />
      <geometry>
        <mesh
          filename="./meshes/right_thumb_tactile_0.STL" />
      </geometry>
    </collision>
  </link>
  <joint
    name="right_thumb_j2_sensor"
    type="fixed">
    <origin
      xyz="0 0 0"
      rpy="0 0 0" />
    <parent
      link="right_thumb_link_2" />
    <child
      link="right_thumb_tactile_0" />
    <axis
      xyz="0 0 0" />
  </joint>
  <link
    name="right_thumb_link_3">
    <inertial>
      <origin
        xyz="0.0149207703549022 -0.00169559683362767 4.88942856025753E-05"
        rpy="0 0 0" />
      <mass
        value="0.020327269172061" />
      <inertia
        ixx="8.54963082609282E-07"
        ixy="-9.00633064469564E-09"
        ixz="5.07245700811023E-09"
        iyy="3.30601806175647E-06"
        iyz="-1.41572033747271E-10"
        izz="2.99491712542649E-06" />
    </inertial>
    <visual>
      <origin
        xyz="0 0 0"
        rpy="0 0 0" />
      <geometry>
        <mesh
          filename="./meshes/right_thumb_link_3.STL" />
      </geometry>
      <material
        name="">
        <color
          rgba="0.792156862745098 0.819607843137255 0.933333333333333 1" />
      </material>
    </visual>
    <collision>
      <origin
        xyz="0 0 0"
        rpy="0 0 0" />
      <geometry>
        <mesh
          filename="./meshes/right_thumb_link_3.STL" />
      </geometry>
    </collision>
  </link>
  <joint
    name="right_thumb_j3"
    type="revolute">
    <origin
      xyz="0 -0.055 0"
      rpy="0 0 -1.5708" />
    <parent
      link="right_thumb_link_2" />
    <child
      link="right_thumb_link_3" />
    <axis
      xyz="0 0 1" />
    <limit
      lower="-0.349"
      upper="1.396"
      effort="0"
      velocity="8.7266" />
  </joint>
  <link
    name="right_thumb_tactile_1">
    <inertial>
      <origin
        xyz="0.0155706486585815 -0.000146379053407579 -0.000922913810506569"
        rpy="0 0 0" />
      <mass
        value="0.00938453614062146" />
      <inertia
        ixx="4.49187444958463E-07"
        ixy="-2.4292552428244E-08"
        ixz="9.9084987842839E-10"
        iyy="6.64256720942517E-07"
        iyz="-9.53790751228822E-09"
        izz="3.44838231268382E-07" />
    </inertial>
    <visual>
      <origin
        xyz="0 0 0"
        rpy="0 0 0" />
      <geometry>
        <mesh
          filename="./meshes/right_thumb_tactile_1.STL" />
      </geometry>
      <material
        name="">
        <color
          rgba="0.792156862745098 0.819607843137255 0.933333333333333 1" />
      </material>
    </visual>
    <collision>
      <origin
        xyz="0 0 0"
        rpy="0 0 0" />
      <geometry>
        <mesh
          filename="./meshes/right_thumb_tactile_1.STL" />
      </geometry>
    </collision>
  </link>
  <joint
    name="right_thumb_j3_sensor"
    type="fixed">
    <origin
      xyz="0 0 0"
      rpy="0 0 0" />
    <parent
      link="right_thumb_link_3" />
    <child
      link="right_thumb_tactile_1" />
    <axis
      xyz="0 0 0" />
  </joint>
  <link
    name="right_thumb_link_4">
    <inertial>
      <origin
        xyz="0.00927282757425404 -0.0017363300522532 -2.90586316738228E-07"
        rpy="0 0 0" />
      <mass
        value="0.00936725934380467" />
      <inertia
        ixx="2.35071198079954E-07"
        ixy="-1.3879832089499E-08"
        ixz="-2.26357936451983E-11"
        iyy="7.42799864234394E-07"
        iyz="1.84348414877981E-12"
        izz="6.54548222522704E-07" />
    </inertial>
    <visual>
      <origin
        xyz="0 0 0"
        rpy="0 0 0" />
      <geometry>
        <mesh
          filename="./meshes/right_thumb_link_4.STL" />
      </geometry>
      <material
        name="">
        <color
          rgba="0.792156862745098 0.819607843137255 0.933333333333333 1" />
      </material>
    </visual>
    <collision>
      <origin
        xyz="0 0 0"
        rpy="0 0 0" />
      <geometry>
        <mesh
          filename="./meshes/right_thumb_link_4.STL" />
      </geometry>
    </collision>
  </link>
  <joint
    name="right_thumb_j4"
    type="revolute">
    <origin
      xyz="0.03 0 0"
      rpy="0 0 0" />
    <parent
      link="right_thumb_link_3" />
    <child
      link="right_thumb_link_4" />
    <axis
      xyz="0 0 1" />
    <limit
      lower="-0.349"
      upper="1.396"
      effort="0"
      velocity="8.7266" />
      <mimic joint="right_thumb_j3" multiplier="1.0" offset="0"/>
  </joint>
  <link
    name="right_thumb_tactile_2">
    <inertial>
      <origin
        xyz="0.0153336175005472 0.000139513120058242 -1.09682940165421E-05"
        rpy="0 0 0" />
      <mass
        value="0.00986648442645367" />
      <inertia
        ixx="2.51853784283472E-07"
        ixy="1.44641281581587E-08"
        ixz="-3.18451056956863E-10"
        iyy="5.0733336829745E-07"
        iyz="-1.73369940114778E-10"
        izz="3.64478409508483E-07" />
    </inertial>
    <visual>
      <origin
        xyz="0 0 0"
        rpy="0 0 0" />
      <geometry>
        <mesh
          filename="./meshes/right_thumb_tactile_2.STL" />
      </geometry>
      <material
        name="">
        <color
          rgba="0.792156862745098 0.819607843137255 0.933333333333333 1" />
      </material>
    </visual>
    <collision>
      <origin
        xyz="0 0 0"
        rpy="0 0 0" />
      <geometry>
        <mesh
          filename="./meshes/right_thumb_tactile_2.STL" />
      </geometry>
    </collision>
  </link>
  <joint
    name="right_thumb_j4_sensor"
    type="fixed">
    <origin
      xyz="0 0 0"
      rpy="0 0 0" />
    <parent
      link="right_thumb_link_4" />
    <child
      link="right_thumb_tactile_2" />
    <axis
      xyz="0 0 0" />
  </joint>
  <link
    name="right_thumb_pad">
    <inertial>
      <origin
        xyz="-0.015 -0.00780000000000002 -1.52190425531124E-05"
        rpy="0 0 0" />
      <mass
        value="8.20481262582145E-06" />
      <inertia
        ixx="2.67867788925158E-12"
        ixy="8.23681150831009E-28"
        ixz="-2.53559409859437E-27"
        iyy="2.76292091095753E-12"
        iyz="-1.79065651224472E-27"
        izz="4.14452782376372E-12" />
    </inertial>
    <visual>
      <origin
        xyz="0 0 0"
        rpy="0 0 0" />
      <geometry>
        <mesh
          filename="./meshes/right_thumb_pad.STL" />
      </geometry>
      <material
        name="">
        <color
          rgba="0.866666666666667 0.866666666666667 0.890196078431372 1" />
      </material>
    </visual>
    <collision>
      <origin
        xyz="0 0 0"
        rpy="0 0 0" />
      <geometry>
        <mesh
          filename="./meshes/right_thumb_pad.STL" />
      </geometry>
    </collision>
  </link>
  <joint
    name="right_thumb_pad"
    type="fixed">
    <origin
      xyz="0.015 0.00779999999999999 0"
      rpy="0 0 0" />
    <parent
      link="right_thumb_link_4" />
    <child
      link="right_thumb_pad" />
    <axis
      xyz="0 0 0" />
  </joint>
  <link
    name="right_thumb_tip">
    <inertial>
      <origin
        xyz="-0.028 6.93889390390723E-18 -1.52190425529997E-05"
        rpy="0 0 0" />
      <mass
        value="8.20481262582145E-06" />
      <inertia
        ixx="2.67867788925158E-12"
        ixy="9.17503607962799E-28"
        ixz="5.40832139261283E-28"
        iyy="2.76292091095753E-12"
        iyz="-2.1497665854043E-27"
        izz="4.14452782376372E-12" />
    </inertial>
    <visual>
      <origin
        xyz="0 0 0"
        rpy="0 0 0" />
      <geometry>
        <mesh
          filename="./meshes/right_thumb_tip.STL" />
      </geometry>
      <material
        name="">
        <color
          rgba="0.866666666666667 0.866666666666667 0.890196078431372 1" />
      </material>
    </visual>
    <collision>
      <origin
        xyz="0 0 0"
        rpy="0 0 0" />
      <geometry>
        <mesh
          filename="./meshes/right_thumb_tip.STL" />
      </geometry>
    </collision>
  </link>
  <joint
    name="right_thumb_tip"
    type="fixed">
    <origin
      xyz="0.028 0 0"
      rpy="0 0 0" />
    <parent
      link="right_thumb_link_4" />
    <child
      link="right_thumb_tip" />
    <axis
      xyz="0 0 0" />
  </joint>
  <link
    name="right_index_link_0">
    <inertial>
      <origin
        xyz="0.00518103249700076 -1.19567339432192E-08 0.000208761354639903"
        rpy="0 0 0" />
      <mass
        value="0.0187941572496829" />
      <inertia
        ixx="8.81994778839317E-07"
        ixy="-2.09676807266413E-13"
        ixz="2.03275560550625E-08"
        iyy="2.16564216035535E-06"
        iyz="-4.12074277020059E-13"
        izz="1.86406350336843E-06" />
    </inertial>
    <visual>
      <origin
        xyz="0 0 0"
        rpy="0 0 0" />
      <geometry>
        <mesh
          filename="./meshes/right_index_link_0.STL" />
      </geometry>
      <material
        name="">
        <color
          rgba="0.792156862745098 0.819607843137255 0.933333333333333 1" />
      </material>
    </visual>
    <collision>
      <origin
        xyz="0 0 0"
        rpy="0 0 0" />
      <geometry>
        <mesh
          filename="./meshes/right_index_link_0.STL" />
      </geometry>
    </collision>
  </link>
  <joint
    name="right_index_j0"
    type="revolute">
    <origin
      xyz="0.0069979 0.034496 0.1155"
      rpy="0 -1.5708 0" />
    <parent
      link="right_palm_link" />
    <child
      link="right_index_link_0" />
    <axis
      xyz="0 0 1" />
    <limit
      lower="-0.436"
      upper="0.436"
      effort="0"
      velocity="8.7266" />
  </joint>
  <link
    name="right_index_link_1">
    <inertial>
      <origin
        xyz="0.0181272616917464 -0.00100981558882494 2.62717940457957E-09"
        rpy="0 0 0" />
      <mass
        value="0.0290954766878931" />
      <inertia
        ixx="1.52993136483585E-06"
        ixy="1.188437355547E-07"
        ixz="-6.91861882327693E-13"
        iyy="9.77314975309016E-06"
        iyz="-7.47729192329556E-13"
        izz="9.44459437080453E-06" />
    </inertial>
    <visual>
      <origin
        xyz="0 0 0"
        rpy="0 0 0" />
      <geometry>
        <mesh
          filename="./meshes/right_index_link_1.STL" />
      </geometry>
      <material
        name="">
        <color
          rgba="0.792156862745098 0.819607843137255 0.933333333333333 1" />
      </material>
    </visual>
    <collision>
      <origin
        xyz="0 0 0"
        rpy="0 0 0" />
      <geometry>
        <mesh
          filename="./meshes/right_index_link_1.STL" />
      </geometry>
    </collision>
  </link>
  <joint
    name="right_index_j1"
    type="revolute">
    <origin
      xyz="0.016 0 0"
      rpy="-1.570795877559 0 0" />
    <parent
      link="right_index_link_0" />
    <child
      link="right_index_link_1" />
    <axis
      xyz="0 0 1" />
    <limit
      lower="-0.349"
      upper="1.5708"
      effort="0"
      velocity="8.7266" />
  </joint>
  <link
    name="right_index_tactile_0">
    <inertial>
      <origin
        xyz="0.0252888233887622 -0.000438388140744088 -7.07457526153074E-05"
        rpy="0 0 0" />
      <mass
        value="0.00892665816512101" />
      <inertia
        ixx="3.36634811281352E-07"
        ixy="5.24371623183532E-09"
        ixz="1.8122561048165E-09"
        iyy="7.97475940563597E-07"
        iyz="4.75687438775283E-10"
        izz="5.88685346572617E-07" />
    </inertial>
    <visual>
      <origin
        xyz="0 0 0"
        rpy="0 0 0" />
      <geometry>
        <mesh
          filename="./meshes/right_index_tactile_0.STL" />
      </geometry>
      <material
        name="">
        <color
          rgba="0.792156862745098 0.819607843137255 0.933333333333333 1" />
      </material>
    </visual>
    <collision>
      <origin
        xyz="0 0 0"
        rpy="0 0 0" />
      <geometry>
        <mesh
          filename="./meshes/right_index_tactile_0.STL" />
      </geometry>
    </collision>
  </link>
  <joint
    name="right_index_j1_sensor"
    type="fixed">
    <origin
      xyz="0 0 0"
      rpy="0 0 0" />
    <parent
      link="right_index_link_1" />
    <child
      link="right_index_tactile_0" />
    <axis
      xyz="0 0 0" />
  </joint>
  <link
    name="right_index_link_2">
    <inertial>
      <origin
        xyz="0.0131267276443713 -0.000547841455176024 1.91054060696971E-08"
        rpy="0 0 0" />
      <mass
        value="0.0111427111396244" />
      <inertia
        ixx="3.40511736739534E-07"
        ixy="-4.76343858848065E-09"
        ixz="-8.30092714136871E-14"
        iyy="1.33006253977743E-06"
        iyz="-1.02300275358507E-12"
        izz="1.24142404792865E-06" />
    </inertial>
    <visual>
      <origin
        xyz="0 0 0"
        rpy="0 0 0" />
      <geometry>
        <mesh
          filename="./meshes/right_index_link_2.STL" />
      </geometry>
      <material
        name="">
        <color
          rgba="0.792156862745098 0.819607843137255 0.933333333333333 1" />
      </material>
    </visual>
    <collision>
      <origin
        xyz="0 0 0"
        rpy="0 0 0" />
      <geometry>
        <mesh
          filename="./meshes/right_index_link_2.STL" />
      </geometry>
    </collision>
  </link>
  <joint
    name="right_index_j2"
    type="revolute">
    <origin
      xyz="0.045 0 0"
      rpy="0 0 0" />
    <parent
      link="right_index_link_1" />
    <child
      link="right_index_link_2" />
    <axis
      xyz="0 0 1" />
    <limit
      lower="-0.0873"
      upper="1.745"
      effort="0"
      velocity="8.7266" />
  </joint>
  <link
    name="right_index_tactile_1">
    <inertial>
      <origin
        xyz="0.0133625735951503 -0.000620109526565754 0.000194823181576285"
        rpy="0 0 0" />
      <mass
        value="0.00363566690918231" />
      <inertia
        ixx="1.38485746254827E-07"
        ixy="-5.0443190525419E-09"
        ixz="1.31215834079762E-09"
        iyy="1.98003864751691E-07"
        iyz="2.82053870295852E-10"
        izz="9.02081851920847E-08" />
    </inertial>
    <visual>
      <origin
        xyz="0 0 0"
        rpy="0 0 0" />
      <geometry>
        <mesh
          filename="./meshes/right_index_tactile_1.STL" />
      </geometry>
      <material
        name="">
        <color
          rgba="0.792156862745098 0.819607843137255 0.933333333333333 1" />
      </material>
    </visual>
    <collision>
      <origin
        xyz="0 0 0"
        rpy="0 0 0" />
      <geometry>
        <mesh
          filename="./meshes/right_index_tactile_1.STL" />
      </geometry>
    </collision>
  </link>
  <joint
    name="right_index_j2_sensor"
    type="fixed">
    <origin
      xyz="0 0 0"
      rpy="0 0 0" />
    <parent
      link="right_index_link_2" />
    <child
      link="right_index_tactile_1" />
    <axis
      xyz="0 0 0" />
    <limit
      lower="0"
      upper="0"
      effort="0"
      velocity="8.7266" />
  </joint>
  <link
    name="right_index_link_3">
    <inertial>
      <origin
        xyz="0.00581688683133458 -0.000909457430452975 1.82732995540613E-08"
        rpy="0 0 0" />
      <mass
        value="0.00518541203449776" />
      <inertia
        ixx="9.72399859692424E-08"
        ixy="1.62213981255196E-08"
        ixz="-4.40298896983362E-13"
        iyy="2.25428004801863E-07"
        iyz="-7.03801987836351E-14"
        izz="2.21171572183738E-07" />
    </inertial>
    <visual>
      <origin
        xyz="0 0 0"
        rpy="0 0 0" />
      <geometry>
        <mesh
          filename="./meshes/right_index_link_3.STL" />
      </geometry>
      <material
        name="">
        <color
          rgba="0.792156862745098 0.819607843137255 0.933333333333333 1" />
      </material>
    </visual>
    <collision>
      <origin
        xyz="0 0 0"
        rpy="0 0 0" />
      <geometry>
        <mesh
          filename="./meshes/right_index_link_3.STL" />
      </geometry>
    </collision>
  </link>
  <joint
    name="right_index_j3"
    type="revolute">
    <origin
      xyz="0.025 0 0"
      rpy="0 0 0" />
    <parent
      link="right_index_link_2" />
    <child
      link="right_index_link_3" />
    <axis
      xyz="0 0 1" />
    <limit
      lower="-0.0873"
      upper="1.745"
      effort="0"
      velocity="8.7266" />
    <mimic joint="right_index_j2" multiplier="1.0" offset="0"/>
  </joint>
  <link
    name="right_index_tactile_2">
    <inertial>
      <origin
        xyz="0.0153340085895587 8.83654923733825E-05 -7.3279503164797E-06"
        rpy="0 0 0" />
      <mass
        value="0.00986650294125371" />
      <inertia
        ixx="2.5195319439835E-07"
        ixy="1.531568500901E-08"
        ixz="-3.19440860453957E-10"
        iyy="5.07235332923071E-07"
        iyz="-1.72413481951111E-10"
        izz="3.64479630832135E-07" />
    </inertial>
    <visual>
      <origin
        xyz="0 0 0"
        rpy="0 0 0" />
      <geometry>
        <mesh
          filename="./meshes/right_index_tactile_2.STL" />
      </geometry>
      <material
        name="">
        <color
          rgba="0.792156862745098 0.819607843137255 0.933333333333333 1" />
      </material>
    </visual>
    <collision>
      <origin
        xyz="0 0 0"
        rpy="0 0 0" />
      <geometry>
        <mesh
          filename="./meshes/right_index_tactile_2.STL" />
      </geometry>
    </collision>
  </link>
  <joint
    name="right_index_j3_sensor"
    type="fixed">
    <origin
      xyz="0 0 0"
      rpy="0 0 0" />
    <parent
      link="right_index_link_3" />
    <child
      link="right_index_tactile_2" />
    <axis
      xyz="0 0 0" />
  </joint>
  <link
    name="right_index_pad">
    <inertial>
      <origin
        xyz="-0.016 -0.00789999999999987 -1.52190425530274E-05"
        rpy="0 0 0" />
      <mass
        value="8.20481262582146E-06" />
      <inertia
        ixx="2.67867788925158E-12"
        ixy="6.71740709568232E-28"
        ixz="1.42963370449508E-27"
        iyy="2.76292091095753E-12"
        iyz="-2.44725750704784E-27"
        izz="4.14452782376372E-12" />
    </inertial>
    <visual>
      <origin
        xyz="0 0 0"
        rpy="0 0 0" />
      <geometry>
        <mesh
          filename="./meshes/right_index_pad.STL" />
      </geometry>
      <material
        name="">
        <color
          rgba="0.866666666666667 0.866666666666667 0.890196078431372 1" />
      </material>
    </visual>
    <collision>
      <origin
        xyz="0 0 0"
        rpy="0 0 0" />
      <geometry>
        <mesh
          filename="./meshes/right_index_pad.STL" />
      </geometry>
    </collision>
  </link>
  <joint
    name="right_index_pad"
    type="fixed">
    <origin
      xyz="0.016 0.00789999999999919 0"
      rpy="0 0 0" />
    <parent
      link="right_index_link_3" />
    <child
      link="right_index_pad" />
    <axis
      xyz="0 0 0" />
  </joint>
  <link
    name="right_index_tip">
    <inertial>
      <origin
        xyz="-0.028 2.20309881449055E-16 -1.52190425530205E-05"
        rpy="0 0 0" />
      <mass
        value="8.20481262582146E-06" />
      <inertia
        ixx="2.67867788925158E-12"
        ixy="4.92616348592834E-28"
        ixz="9.61590636261185E-28"
        iyy="2.76292091095753E-12"
        iyz="-3.78948754425724E-27"
        izz="4.14452782376372E-12" />
    </inertial>
    <visual>
      <origin
        xyz="0 0 0"
        rpy="0 0 0" />
      <geometry>
        <mesh
          filename="./meshes/right_index_tip.STL" />
      </geometry>
      <material
        name="">
        <color
          rgba="0.866666666666667 0.866666666666667 0.890196078431372 1" />
      </material>
    </visual>
    <collision>
      <origin
        xyz="0 0 0"
        rpy="0 0 0" />
      <geometry>
        <mesh
          filename="./meshes/right_index_tip.STL" />
      </geometry>
    </collision>
  </link>
  <joint
    name="right_index_tip"
    type="fixed">
    <origin
      xyz="0.028 0 0"
      rpy="0 0 0" />
    <parent
      link="right_index_link_3" />
    <child
      link="right_index_tip" />
    <axis
      xyz="0 0 0" />
  </joint>
  <link
    name="right_middle_link_0">
    <inertial>
      <origin
        xyz="0.00518103249700078 -1.19567339484233E-08 0.000208761354639874"
        rpy="0 0 0" />
      <mass
        value="0.0187941572496829" />
      <inertia
        ixx="8.81994778839318E-07"
        ixy="-2.09676807245369E-13"
        ixz="2.03275560550676E-08"
        iyy="2.16564216035534E-06"
        iyz="-4.12074277099656E-13"
        izz="1.86406350336843E-06" />
    </inertial>
    <visual>
      <origin
        xyz="0 0 0"
        rpy="0 0 0" />
      <geometry>
        <mesh
          filename="./meshes/right_middle_link_0.STL" />
      </geometry>
      <material
        name="">
        <color
          rgba="0.792156862745098 0.819607843137255 0.933333333333333 1" />
      </material>
    </visual>
    <collision>
      <origin
        xyz="0 0 0"
        rpy="0 0 0" />
      <geometry>
        <mesh
          filename="./meshes/right_middle_link_0.STL" />
      </geometry>
    </collision>
  </link>
  <joint
    name="right_middle_j0"
    type="revolute">
    <origin
      xyz="0.0069979 0.011496 0.1185"
      rpy="0 -1.5708 0" />
    <parent
      link="right_palm_link" />
    <child
      link="right_middle_link_0" />
    <axis
      xyz="0 0 1" />
    <limit
      lower="-0.436"
      upper="0.436"
      effort="0"
      velocity="8.7266" />
  </joint>
  <link
    name="right_middle_link_1">
    <inertial>
      <origin
        xyz="0.0181272616918263 -0.00100981558888012 2.62724171931628E-09"
        rpy="0 0 0" />
      <mass
        value="0.0290954766874994" />
      <inertia
        ixx="1.52993136482018E-06"
        ixy="1.18843735544504E-07"
        ixz="-6.91850183711679E-13"
        iyy="9.77314975306575E-06"
        iyz="-7.47736946841774E-13"
        izz="9.44459437078222E-06" />
    </inertial>
    <visual>
      <origin
        xyz="0 0 0"
        rpy="0 0 0" />
      <geometry>
        <mesh
          filename="./meshes/right_middle_link_1.STL" />
      </geometry>
      <material
        name="">
        <color
          rgba="0.792156862745098 0.819607843137255 0.933333333333333 1" />
      </material>
    </visual>
    <collision>
      <origin
        xyz="0 0 0"
        rpy="0 0 0" />
      <geometry>
        <mesh
          filename="./meshes/right_middle_link_1.STL" />
      </geometry>
    </collision>
  </link>
  <joint
    name="right_middle_j1"
    type="revolute">
    <origin
      xyz="0.016 0 0"
      rpy="-1.5708 0 0" />
    <parent
      link="right_middle_link_0" />
    <child
      link="right_middle_link_1" />
    <axis
      xyz="0 0 1" />
    <limit
      lower="-0.349"
      upper="1.5708"
      effort="0"
      velocity="8.7266" />
  </joint>
  <link
    name="right_middle_link_2">
    <inertial>
      <origin
        xyz="0.013126987418959 -0.000541581214596073 1.91025937689576E-08"
        rpy="0 0 0" />
      <mass
        value="0.0111427111396243" />
      <inertia
        ixx="3.4051650519725E-07"
        ixy="-5.23535630212223E-09"
        ixz="-8.23283756151459E-14"
        iyy="1.33005777131971E-06"
        iyz="-1.02304111201239E-12"
        izz="1.24142404792865E-06" />
    </inertial>
    <visual>
      <origin
        xyz="0 0 0"
        rpy="0 0 0" />
      <geometry>
        <mesh
          filename="./meshes/right_middle_link_2.STL" />
      </geometry>
      <material
        name="">
        <color
          rgba="0.792156862745098 0.819607843137255 0.933333333333333 1" />
      </material>
    </visual>
    <collision>
      <origin
        xyz="0 0 0"
        rpy="0 0 0" />
      <geometry>
        <mesh
          filename="./meshes/right_middle_link_2.STL" />
      </geometry>
    </collision>
  </link>
  <joint
    name="right_middle_j2"
    type="revolute">
    <origin
      xyz="0.045 0 0"
      rpy="0 0 -0.0004769" />
    <parent
      link="right_middle_link_1" />
    <child
      link="right_middle_link_2" />
    <axis
      xyz="0 0 1" />
    <limit
      lower="-0.0873"
      upper="1.745"
      effort="0"
      velocity="8.7266" />
  </joint>
  <link
    name="right_middle_tactile_1">
    <inertial>
      <origin
        xyz="0.0133628678078449 -0.000613736802086449 0.000194823178722658"
        rpy="0 0 0" />
      <mass
        value="0.00363566690918773" />
      <inertia
        ixx="1.38490571095407E-07"
        ixy="-5.07270113538162E-09"
        ixz="1.31202366855878E-09"
        iyy="1.97999039912536E-07"
        iyz="2.82679611701763E-10"
        izz="9.02081851919142E-08" />
    </inertial>
    <visual>
      <origin
        xyz="0 0 0"
        rpy="0 0 0" />
      <geometry>
        <mesh
          filename="./meshes/right_middle_tactile_1.STL" />
      </geometry>
      <material
        name="">
        <color
          rgba="0.792156862745098 0.819607843137255 0.933333333333333 1" />
      </material>
    </visual>
    <collision>
      <origin
        xyz="0 0 0"
        rpy="0 0 0" />
      <geometry>
        <mesh
          filename="./meshes/right_middle_tactile_1.STL" />
      </geometry>
    </collision>
  </link>
  <joint
    name="right_middle_j2_sensor"
    type="fixed">
    <origin
      xyz="0 0 0"
      rpy="0 0 0" />
    <parent
      link="right_middle_link_2" />
    <child
      link="right_middle_tactile_1" />
    <axis
      xyz="0 0 0" />
  </joint>
  <link
    name="right_middle_link_3">
    <inertial>
      <origin
        xyz="0.00581688683133452 -0.000909457430452941 1.82732995627349E-08"
        rpy="0 0 0" />
      <mass
        value="0.00518541203449776" />
      <inertia
        ixx="9.72399859692423E-08"
        ixy="1.62213981255189E-08"
        ixz="-4.40298897005161E-13"
        iyy="2.25428004801864E-07"
        iyz="-7.03801988269117E-14"
        izz="2.21171572183738E-07" />
    </inertial>
    <visual>
      <origin
        xyz="0 0 0"
        rpy="0 0 0" />
      <geometry>
        <mesh
          filename="./meshes/right_middle_link_3.STL" />
      </geometry>
      <material
        name="">
        <color
          rgba="0.792156862745098 0.819607843137255 0.933333333333333 1" />
      </material>
    </visual>
    <collision>
      <origin
        xyz="0 0 0"
        rpy="0 0 0" />
      <geometry>
        <mesh
          filename="./meshes/right_middle_link_3.STL" />
      </geometry>
    </collision>
  </link>
  <joint
    name="right_middle_j3"
    type="revolute">
    <origin
      xyz="0.025 1.1923E-05 0"
      rpy="0 0 0.0004769" />
    <parent
      link="right_middle_link_2" />
    <child
      link="right_middle_link_3" />
    <axis
      xyz="0 0 1" />
    <limit
      lower="-0.0873"
      upper="1.745"
      effort="0"
      velocity="8.7266" />
    <mimic joint="right_middle_j2" multiplier="1.0" offset="0"/>
  </joint>
  <link
    name="right_middle_tactile_2">
    <inertial>
      <origin
        xyz="0.0153340086196094 8.8365425694569E-05 -7.3277822671431E-06"
        rpy="0 0 0" />
      <mass
        value="0.00986650306941366" />
      <inertia
        ixx="2.51953197734686E-07"
        ixy="1.53156846585897E-08"
        ixz="-3.19438706926866E-10"
        iyy="5.07235339340164E-07"
        iyz="-1.7241378821339E-10"
        izz="3.64479634093641E-07" />
    </inertial>
    <visual>
      <origin
        xyz="0 0 0"
        rpy="0 0 0" />
      <geometry>
        <mesh
          filename="./meshes/right_middle_tactile_2.STL" />
      </geometry>
      <material
        name="">
        <color
          rgba="0.792156862745098 0.819607843137255 0.933333333333333 1" />
      </material>
    </visual>
    <collision>
      <origin
        xyz="0 0 0"
        rpy="0 0 0" />
      <geometry>
        <mesh
          filename="./meshes/right_middle_tactile_2.STL" />
      </geometry>
    </collision>
  </link>
  <joint
    name="right_middle_j3_sensor"
    type="fixed">
    <origin
      xyz="0 0 0"
      rpy="0 0 0" />
    <parent
      link="right_middle_link_3" />
    <child
      link="right_middle_tactile_2" />
    <axis
      xyz="0 0 0" />
  </joint>
  <link
    name="right_middle_pad">
    <inertial>
      <origin
        xyz="-0.016 -0.00790000000000033 -1.52190425530066E-05"
        rpy="0 0 0" />
      <mass
        value="8.20481262582145E-06" />
      <inertia
        ixx="2.67867788925157E-12"
        ixy="-1.79831446692213E-27"
        ixz="-7.80923393626903E-28"
        iyy="2.76292091095752E-12"
        iyz="-8.19008807727435E-28"
        izz="4.14452782376371E-12" />
    </inertial>
    <visual>
      <origin
        xyz="0 0 0"
        rpy="0 0 0" />
      <geometry>
        <mesh
          filename="./meshes/right_middle_pad.STL" />
      </geometry>
      <material
        name="">
        <color
          rgba="0.866666666666667 0.866666666666667 0.890196078431372 1" />
      </material>
    </visual>
    <collision>
      <origin
        xyz="0 0 0"
        rpy="0 0 0" />
      <geometry>
        <mesh
          filename="./meshes/right_middle_pad.STL" />
      </geometry>
    </collision>
  </link>
  <joint
    name="right_middle_pad"
    type="fixed">
    <origin
      xyz="0.0160000000000002 0.00789999999999927 0"
      rpy="0 0 0" />
    <parent
      link="right_middle_link_3" />
    <child
      link="right_middle_pad" />
    <axis
      xyz="0 0 0" />
  </joint>
  <link
    name="right_middle_tip">
    <inertial>
      <origin
        xyz="-0.028 -5.82867087928207E-16 -1.52190425530187E-05"
        rpy="0 0 0" />
      <mass
        value="8.20481262582146E-06" />
      <inertia
        ixx="2.67867788925158E-12"
        ixy="-1.82421205833913E-27"
        ixz="6.00919710509385E-28"
        iyy="2.76292091095753E-12"
        iyz="-2.98422102377016E-27"
        izz="4.14452782376372E-12" />
    </inertial>
    <visual>
      <origin
        xyz="0 0 0"
        rpy="0 0 0" />
      <geometry>
        <mesh
          filename="./meshes/right_middle_tip.STL" />
      </geometry>
      <material
        name="">
        <color
          rgba="0.866666666666667 0.866666666666667 0.890196078431372 1" />
      </material>
    </visual>
    <collision>
      <origin
        xyz="0 0 0"
        rpy="0 0 0" />
      <geometry>
        <mesh
          filename="./meshes/right_middle_tip.STL" />
      </geometry>
    </collision>
  </link>
  <joint
    name="right_middle_tip"
    type="fixed">
    <origin
      xyz="0.0280000000000001 0 0"
      rpy="0 0 0" />
    <parent
      link="right_middle_link_3" />
    <child
      link="right_middle_tip" />
    <axis
      xyz="0 0 0" />
  </joint>
  <link
    name="right_middle_tactile_0">
    <inertial>
      <origin
        xyz="0.025288827655078 -0.000438398987762033 -7.07414472094475E-05"
        rpy="0 0 0" />
      <mass
        value="0.00892666891987732" />
      <inertia
        ixx="3.36634997406483E-07"
        ixy="5.24371624821559E-09"
        ixz="1.81210715175707E-09"
        iyy="7.97476576113434E-07"
        iyz="4.75717414874231E-10"
        izz="5.88685842004942E-07" />
    </inertial>
    <visual>
      <origin
        xyz="0 0 0"
        rpy="0 0 0" />
      <geometry>
        <mesh
          filename="./meshes/right_middle_tactile_0.STL" />
      </geometry>
      <material
        name="">
        <color
          rgba="0.792156862745098 0.819607843137255 0.933333333333333 1" />
      </material>
    </visual>
    <collision>
      <origin
        xyz="0 0 0"
        rpy="0 0 0" />
      <geometry>
        <mesh
          filename="./meshes/right_middle_tactile_0.STL" />
      </geometry>
    </collision>
  </link>
  <joint
    name="right_middle_j1_sensor"
    type="fixed">
    <origin
      xyz="0 0 0"
      rpy="0 0 0" />
    <parent
      link="right_middle_link_1" />
    <child
      link="right_middle_tactile_0" />
    <axis
      xyz="0 0 0" />
  </joint>
  <link
    name="right_ring_link_0">
    <inertial>
      <origin
        xyz="0.00518103249700075 -1.19567339501581E-08 0.000208761354639902"
        rpy="0 0 0" />
      <mass
        value="0.0187941572496829" />
      <inertia
        ixx="8.81994778839318E-07"
        ixy="-2.09676807467208E-13"
        ixz="2.03275560550629E-08"
        iyy="2.16564216035535E-06"
        iyz="-4.12074277071846E-13"
        izz="1.86406350336843E-06" />
    </inertial>
    <visual>
      <origin
        xyz="0 0 0"
        rpy="0 0 0" />
      <geometry>
        <mesh
          filename="./meshes/right_ring_link_0.STL" />
      </geometry>
      <material
        name="">
        <color
          rgba="0.792156862745098 0.819607843137255 0.933333333333333 1" />
      </material>
    </visual>
    <collision>
      <origin
        xyz="0 0 0"
        rpy="0 0 0" />
      <geometry>
        <mesh
          filename="./meshes/right_ring_link_0.STL" />
      </geometry>
    </collision>
  </link>
  <joint
    name="right_ring_j0"
    type="revolute">
    <origin
      xyz="0.0069979 -0.011503 0.1155"
      rpy="0 -1.5708 0" />
    <parent
      link="right_palm_link" />
    <child
      link="right_ring_link_0" />
    <axis
      xyz="0 0 1" />
    <limit
      lower="-0.436"
      upper="0.436"
      effort="0"
      velocity="8.7266" />
  </joint>
  <link
    name="right_ring_link_1">
    <inertial>
      <origin
        xyz="0.0181277412147468 -0.00100117052517637 2.6233958200228E-09"
        rpy="0 0 0" />
      <mass
        value="0.0290954766872578" />
      <inertia
        ixx="1.52981988572092E-06"
        ixy="1.14912464792626E-07"
        ixz="-6.89790876730234E-13"
        iyy="9.77326123214125E-06"
        iyz="-7.48096045871977E-13"
        izz="9.44459437076907E-06" />
    </inertial>
    <visual>
      <origin
        xyz="0 0 0"
        rpy="0 0 0" />
      <geometry>
        <mesh
          filename="./meshes/right_ring_link_1.STL" />
      </geometry>
      <material
        name="">
        <color
          rgba="0.792156862745098 0.819607843137255 0.933333333333333 1" />
      </material>
    </visual>
    <collision>
      <origin
        xyz="0 0 0"
        rpy="0 0 0" />
      <geometry>
        <mesh
          filename="./meshes/right_ring_link_1.STL" />
      </geometry>
    </collision>
  </link>
  <joint
    name="right_ring_j1"
    type="revolute">
    <origin
      xyz="0.016 0 0"
      rpy="-1.5708 -0.0004769 0" />
    <parent
      link="right_ring_link_0" />
    <child
      link="right_ring_link_1" />
    <axis
      xyz="0 0 1" />
    <limit
      lower="-0.349"
      upper="1.5708"
      effort="0"
      velocity="8.7266" />
  </joint>
  <link
    name="right_ring_tactile_0">
    <inertial>
      <origin
        xyz="0.0252890321279993 -0.000426331874284413 -7.07437041742118E-05"
        rpy="0 0 0" />
      <mass
        value="0.0089266622621125" />
      <inertia
        ixx="3.36630004965721E-07"
        ixy="5.02394501210385E-09"
        ixz="1.81192372550505E-09"
        iyy="7.97481188955242E-07"
        iyz="4.76569623934577E-10"
        izz="5.88685619351876E-07" />
    </inertial>
    <visual>
      <origin
        xyz="0 0 0"
        rpy="0 0 0" />
      <geometry>
        <mesh
          filename="./meshes/right_ring_tactile_0.STL" />
      </geometry>
      <material
        name="">
        <color
          rgba="0.792156862745098 0.819607843137255 0.933333333333333 1" />
      </material>
    </visual>
    <collision>
      <origin
        xyz="0 0 0"
        rpy="0 0 0" />
      <geometry>
        <mesh
          filename="./meshes/right_ring_tactile_0.STL" />
      </geometry>
    </collision>
  </link>
  <joint
    name="right_ring_tactile_0"
    type="fixed">
    <origin
      xyz="0 0 0"
      rpy="0 0 0" />
    <parent
      link="right_ring_link_1" />
    <child
      link="right_ring_tactile_0" />
    <axis
      xyz="0 0 0" />
  </joint>
  <link
    name="right_ring_link_2">
    <inertial>
      <origin
        xyz="0.0131267276443713 -0.000547841455176019 1.91054060749013E-08"
        rpy="0 0 0" />
      <mass
        value="0.0111427111396244" />
      <inertia
        ixx="3.40511736739534E-07"
        ixy="-4.763438588481E-09"
        ixz="-8.30092717477725E-14"
        iyy="1.33006253977743E-06"
        iyz="-1.02300275356183E-12"
        izz="1.24142404792865E-06" />
    </inertial>
    <visual>
      <origin
        xyz="0 0 0"
        rpy="0 0 0" />
      <geometry>
        <mesh
          filename="./meshes/right_ring_link_2.STL" />
      </geometry>
      <material
        name="">
        <color
          rgba="0.792156862745098 0.819607843137255 0.933333333333333 1" />
      </material>
    </visual>
    <collision>
      <origin
        xyz="0 0 0"
        rpy="0 0 0" />
      <geometry>
        <mesh
          filename="./meshes/right_ring_link_2.STL" />
      </geometry>
    </collision>
  </link>
  <joint
    name="right_ring_j2"
    type="revolute">
    <origin
      xyz="0.045 2.1461E-05 0"
      rpy="0 0 0.0004769" />
    <parent
      link="right_ring_link_1" />
    <child
      link="right_ring_link_2" />
    <axis
      xyz="0 0 1" />
    <limit
      lower="-0.0873"
      upper="1.745"
      effort="0"
      velocity="8.7266" />
  </joint>
  <link
    name="right_ring_tactile_1">
    <inertial>
      <origin
        xyz="0.0133625733978299 -0.000620109429886369 0.000194823440938432"
        rpy="0 0 0" />
      <mass
        value="0.00363566684156878" />
      <inertia
        ixx="1.38485738100761E-07"
        ixy="-5.04432140486394E-09"
        ixz="1.31215182409861E-09"
        iyy="1.98003851504149E-07"
        iyz="2.82058272907437E-10"
        izz="9.02081822092372E-08" />
    </inertial>
    <visual>
      <origin
        xyz="0 0 0"
        rpy="0 0 0" />
      <geometry>
        <mesh
          filename="./meshes/right_ring_tactile_1.STL" />
      </geometry>
      <material
        name="">
        <color
          rgba="0.792156862745098 0.819607843137255 0.933333333333333 1" />
      </material>
    </visual>
    <collision>
      <origin
        xyz="0 0 0"
        rpy="0 0 0" />
      <geometry>
        <mesh
          filename="./meshes/right_ring_tactile_1.STL" />
      </geometry>
    </collision>
  </link>
  <joint
    name="right_ring_j2_sensor"
    type="fixed">
    <origin
      xyz="0 0 0"
      rpy="0 0 0" />
    <parent
      link="right_ring_link_2" />
    <child
      link="right_ring_tactile_1" />
    <axis
      xyz="0 0 0" />
  </joint>
  <link
    name="right_ring_link_3">
    <inertial>
      <origin
        xyz="0.00581688683133458 -0.000909457430452972 1.82732995627349E-08"
        rpy="0 0 0" />
      <mass
        value="0.00518541203449777" />
      <inertia
        ixx="9.72399859692426E-08"
        ixy="1.62213981255195E-08"
        ixz="-4.40298896975811E-13"
        iyy="2.25428004801864E-07"
        iyz="-7.03801988730706E-14"
        izz="2.21171572183738E-07" />
    </inertial>
    <visual>
      <origin
        xyz="0 0 0"
        rpy="0 0 0" />
      <geometry>
        <mesh
          filename="./meshes/right_ring_link_3.STL" />
      </geometry>
      <material
        name="">
        <color
          rgba="0.792156862745098 0.819607843137255 0.933333333333333 1" />
      </material>
    </visual>
    <collision>
      <origin
        xyz="0 0 0"
        rpy="0 0 0" />
      <geometry>
        <mesh
          filename="./meshes/right_ring_link_3.STL" />
      </geometry>
    </collision>
  </link>
  <joint
    name="right_ring_j3"
    type="revolute">
    <origin
      xyz="0.025 0 0"
      rpy="0 0 0" />
    <parent
      link="right_ring_link_2" />
    <child
      link="right_ring_link_3" />
    <axis
      xyz="0 0 1" />
    <limit
      lower="-0.0873"
      upper="1.745"
      effort="0"
      velocity="8.7266" />
    <mimic joint="right_ring_j2" multiplier="1.0" offset="0"/>
  </joint>
  <link
    name="right_ring_tactile_2">
    <inertial>
      <origin
        xyz="0.0153340086129073 8.83654385804332E-05 -7.32818794210201E-06"
        rpy="0 0 0" />
      <mass
        value="0.00986650304596387" />
      <inertia
        ixx="2.51953197265764E-07"
        ixy="1.53156847119519E-08"
        ixz="-3.19437091920444E-10"
        iyy="5.07235338017723E-07"
        iyz="-1.72412313689683E-10"
        izz="3.64479633227303E-07" />
    </inertial>
    <visual>
      <origin
        xyz="0 0 0"
        rpy="0 0 0" />
      <geometry>
        <mesh
          filename="./meshes/right_ring_tactile_2.STL" />
      </geometry>
      <material
        name="">
        <color
          rgba="0.792156862745098 0.819607843137255 0.933333333333333 1" />
      </material>
    </visual>
    <collision>
      <origin
        xyz="0 0 0"
        rpy="0 0 0" />
      <geometry>
        <mesh
          filename="./meshes/right_ring_tactile_2.STL" />
      </geometry>
    </collision>
  </link>
  <joint
    name="right_ring_j3_sensor"
    type="fixed">
    <origin
      xyz="0 0 0"
      rpy="0 0 0" />
    <parent
      link="right_ring_link_3" />
    <child
      link="right_ring_tactile_2" />
    <axis
      xyz="0 0 0" />
  </joint>
  <link
    name="right_ring_pad">
    <inertial>
      <origin
        xyz="-0.0159962306453115 -0.00790762955948942 -1.52154901614989E-05"
        rpy="0 0 0" />
      <mass
        value="8.20481262582145E-06" />
      <inertia
        ixx="2.67867790841152E-12"
        ixy="-4.01757611556362E-17"
        ixz="1.80506064922496E-23"
        iyy="2.76292089179786E-12"
        iyz="6.20667507228861E-19"
        izz="4.14452782376344E-12" />
    </inertial>
    <visual>
      <origin
        xyz="0 0 0"
        rpy="0 0 0" />
      <geometry>
        <mesh
          filename="./meshes/right_ring_pad.STL" />
      </geometry>
      <material
        name="">
        <color
          rgba="0.866666666666667 0.866666666666667 0.890196078431372 1" />
      </material>
    </visual>
    <collision>
      <origin
        xyz="0 0 0"
        rpy="0 0 0" />
      <geometry>
        <mesh
          filename="./meshes/right_ring_pad.STL" />
      </geometry>
    </collision>
  </link>
  <joint
    name="right_ring_pad"
    type="fixed">
    <origin
      xyz="0.016 0.0078999999999992 0"
      rpy="0 0 -0.000476903207335163" />
    <parent
      link="right_ring_link_3" />
    <child
      link="right_ring_pad" />
    <axis
      xyz="0 0 0" />
  </joint>
  <link
    name="right_ring_tip">
    <inertial>
      <origin
        xyz="-0.0279999968158867 -1.3353296136131E-05 -1.52190365542305E-05"
        rpy="0 0 0" />
      <mass
        value="8.20481262582144E-06" />
      <inertia
        ixx="2.67867790841152E-12"
        ixy="-4.017576115541E-17"
        ixz="1.80488975943981E-23"
        iyy="2.76292089179785E-12"
        iyz="6.20667508209148E-19"
        izz="4.14452782376343E-12" />
    </inertial>
    <visual>
      <origin
        xyz="0 0 0"
        rpy="0 0 0" />
      <geometry>
        <mesh
          filename="./meshes/right_ring_tip.STL" />
      </geometry>
      <material
        name="">
        <color
          rgba="0.866666666666667 0.866666666666667 0.890196078431372 1" />
      </material>
    </visual>
    <collision>
      <origin
        xyz="0 0 0"
        rpy="0 0 0" />
      <geometry>
        <mesh
          filename="./meshes/right_ring_tip.STL" />
      </geometry>
    </collision>
  </link>
  <joint
    name="right_ring_tip"
    type="fixed">
    <origin
      xyz="0.028 0 0"
      rpy="0 0 -0.000476903207335163" />
    <parent
      link="right_ring_link_3" />
    <child
      link="right_ring_tip" />
    <axis
      xyz="0 0 0" />
  </joint>
  <link
    name="right_pinky_link_0">
    <inertial>
      <origin
        xyz="0.00518103249700078 -1.1956733957097E-08 0.000208761354639883"
        rpy="0 0 0" />
      <mass
        value="0.0187941572496829" />
      <inertia
        ixx="8.81994778839322E-07"
        ixy="-2.09676806342128E-13"
        ixz="2.0327556055065E-08"
        iyy="2.16564216035535E-06"
        iyz="-4.12074277130513E-13"
        izz="1.86406350336843E-06" />
    </inertial>
    <visual>
      <origin
        xyz="0 0 0"
        rpy="0 0 0" />
      <geometry>
        <mesh
          filename="./meshes/right_pinky_link_0.STL" />
      </geometry>
      <material
        name="">
        <color
          rgba="0.792156862745098 0.819607843137255 0.933333333333333 1" />
      </material>
    </visual>
    <collision>
      <origin
        xyz="0 0 0"
        rpy="0 0 0" />
      <geometry>
        <mesh
          filename="./meshes/right_pinky_link_0.STL" />
      </geometry>
    </collision>
  </link>
  <joint
    name="right_pinky_j0"
    type="revolute">
    <origin
      xyz="0.0069979 -0.034504 0.1125"
      rpy="0 -1.5708 0" />
    <parent
      link="right_palm_link" />
    <child
      link="right_pinky_link_0" />
    <axis
      xyz="0 0 1" />
    <limit
      lower="-0.436"
      upper="0.436"
      effort="0"
      velocity="8.7266" />
  </joint>
  <link
    name="right_pinky_link_1">
    <inertial>
      <origin
        xyz="0.0181272616918263 -0.00100981558888017 2.62724172278572E-09"
        rpy="0 0 0" />
      <mass
        value="0.0290954766874994" />
      <inertia
        ixx="1.52993136482019E-06"
        ixy="1.18843735544526E-07"
        ixz="-6.91850182200478E-13"
        iyy="9.77314975306577E-06"
        iyz="-7.47736946978285E-13"
        izz="9.44459437078224E-06" />
    </inertial>
    <visual>
      <origin
        xyz="0 0 0"
        rpy="0 0 0" />
      <geometry>
        <mesh
          filename="./meshes/right_pinky_link_1.STL" />
      </geometry>
      <material
        name="">
        <color
          rgba="0.792156862745098 0.819607843137255 0.933333333333333 1" />
      </material>
    </visual>
    <collision>
      <origin
        xyz="0 0 0"
        rpy="0 0 0" />
      <geometry>
        <mesh
          filename="./meshes/right_pinky_link_1.STL" />
      </geometry>
    </collision>
  </link>
  <joint
    name="right_pinky_j1"
    type="revolute">
    <origin
      xyz="0.016 0 0"
      rpy="-1.5708 0 0" />
    <parent
      link="right_pinky_link_0" />
    <child
      link="right_pinky_link_1" />
    <axis
      xyz="0 0 1" />
    <limit
      lower="-0.349"
      upper="1.5708"
      effort="0"
      velocity="8.7266" />
  </joint>
  <link
    name="right_pinky_tactile_0">
    <inertial>
      <origin
        xyz="0.0252888233889428 -0.000438388140702666 -7.07457526702635E-05"
        rpy="0 0 0" />
      <mass
        value="0.00892665816501502" />
      <inertia
        ixx="3.36634811281142E-07"
        ixy="5.24371623159477E-09"
        ixz="1.81225610538471E-09"
        iyy="7.97475940563228E-07"
        iyz="4.756874387394E-10"
        izz="5.88685346572688E-07" />
    </inertial>
    <visual>
      <origin
        xyz="0 0 0"
        rpy="0 0 0" />
      <geometry>
        <mesh
          filename="./meshes/right_pinky_tactile_0.STL" />
      </geometry>
      <material
        name="">
        <color
          rgba="0.792156862745098 0.819607843137255 0.933333333333333 1" />
      </material>
    </visual>
    <collision>
      <origin
        xyz="0 0 0"
        rpy="0 0 0" />
      <geometry>
        <mesh
          filename="./meshes/right_pinky_tactile_0.STL" />
      </geometry>
    </collision>
  </link>
  <joint
    name="right_pinky_j1_sensor"
    type="fixed">
    <origin
      xyz="0 0 0"
      rpy="0 0 0" />
    <parent
      link="right_pinky_link_1" />
    <child
      link="right_pinky_tactile_0" />
    <axis
      xyz="0 0 0" />
  </joint>
  <link
    name="right_pinky_link_2">
    <inertial>
      <origin
        xyz="0.013126987418959 -0.000541581214596265 1.91025937637535E-08"
        rpy="0 0 0" />
      <mass
        value="0.0111427111396244" />
      <inertia
        ixx="3.4051650519725E-07"
        ixy="-5.23535630210767E-09"
        ixz="-8.23283758981318E-14"
        iyy="1.33005777131971E-06"
        iyz="-1.02304111203234E-12"
        izz="1.24142404792866E-06" />
    </inertial>
    <visual>
      <origin
        xyz="0 0 0"
        rpy="0 0 0" />
      <geometry>
        <mesh
          filename="./meshes/right_pinky_link_2.STL" />
      </geometry>
      <material
        name="">
        <color
          rgba="0.792156862745098 0.819607843137255 0.933333333333333 1" />
      </material>
    </visual>
    <collision>
      <origin
        xyz="0 0 0"
        rpy="0 0 0" />
      <geometry>
        <mesh
          filename="./meshes/right_pinky_link_2.STL" />
      </geometry>
    </collision>
  </link>
  <joint
    name="right_pinky_j2"
    type="revolute">
    <origin
      xyz="0.045 0 0"
      rpy="0 0 -0.0004769" />
    <parent
      link="right_pinky_link_1" />
    <child
      link="right_pinky_link_2" />
    <axis
      xyz="0 0 1" />
    <limit
      lower="-0.0873"
      upper="1.745"
      effort="0"
      velocity="8.7266" />
  </joint>
  <link
    name="right_pinky_tactile_1">
    <inertial>
      <origin
        xyz="0.0133628678066478 -0.00061373686719834 0.000194823171161186"
        rpy="0 0 0" />
      <mass
        value="0.00363566688942038" />
      <inertia
        ixx="1.38490571723737E-07"
        ixy="-5.07270060029569E-09"
        ixz="1.31202433149499E-09"
        iyy="1.97999040935822E-07"
        iyz="2.82678817726179E-10"
        izz="9.02081851956967E-08" />
    </inertial>
    <visual>
      <origin
        xyz="0 0 0"
        rpy="0 0 0" />
      <geometry>
        <mesh
          filename="./meshes/right_pinky_tactile_1.STL" />
      </geometry>
      <material
        name="">
        <color
          rgba="0.792156862745098 0.819607843137255 0.933333333333333 1" />
      </material>
    </visual>
    <collision>
      <origin
        xyz="0 0 0"
        rpy="0 0 0" />
      <geometry>
        <mesh
          filename="./meshes/right_pinky_tactile_1.STL" />
      </geometry>
    </collision>
  </link>
  <joint
    name="right_pinky_tactile_1"
    type="fixed">
    <origin
      xyz="0 0 0"
      rpy="0 0 0" />
    <parent
      link="right_pinky_link_2" />
    <child
      link="right_pinky_tactile_1" />
    <axis
      xyz="0 0 0" />
  </joint>
  <link
    name="right_pinky_link_3">
    <inertial>
      <origin
        xyz="0.00581731989295267 -0.000906683235434067 1.82720533287162E-08"
        rpy="0 0 0" />
      <mass
        value="0.00518541203449776" />
      <inertia
        ixx="9.72245430542356E-08"
        ixy="1.6160257485055E-08"
        ixz="-4.4023872927688E-13"
        iyy="2.2544344771687E-07"
        iyz="-7.05936334638637E-14"
        izz="2.21171572183739E-07" />
    </inertial>
    <visual>
      <origin
        xyz="0 0 0"
        rpy="0 0 0" />
      <geometry>
        <mesh
          filename="./meshes/right_pinky_link_3.STL" />
      </geometry>
      <material
        name="">
        <color
          rgba="0.792156862745098 0.819607843137255 0.933333333333333 1" />
      </material>
    </visual>
    <collision>
      <origin
        xyz="0 0 0"
        rpy="0 0 0" />
      <geometry>
        <mesh
          filename="./meshes/right_pinky_link_3.STL" />
      </geometry>
    </collision>
  </link>
  <joint
    name="right_pinky_j3"
    type="revolute">
    <origin
      xyz="0.025 1.1923E-05 0"
      rpy="0 0 0" />
    <parent
      link="right_pinky_link_2" />
    <child
      link="right_pinky_link_3" />
    <axis
      xyz="0 0 1" />
    <limit
      lower="-0.0873"
      upper="1.745"
      effort="0"
      velocity="8.7266" />
    <mimic joint="right_pinky_j2" multiplier="1.0" offset="0"/>
  </joint>
  <link
    name="right_pinky_tactile_2">
    <inertial>
      <origin
        xyz="0.0153339648062042 9.56784639174141E-05 -7.32812401998267E-06"
        rpy="0 0 0" />
      <mass
        value="0.0098665026793508" />
      <inertia
        ixx="2.51938635394195E-07"
        ixy="1.51939329018299E-08"
        ixz="-3.19359347483268E-10"
        iyy="5.07249877262976E-07"
        iyz="-1.72565292484588E-10"
        izz="3.64479633837592E-07" />
    </inertial>
    <visual>
      <origin
        xyz="0 0 0"
        rpy="0 0 0" />
      <geometry>
        <mesh
          filename="./meshes/right_pinky_tactile_2.STL" />
      </geometry>
      <material
        name="">
        <color
          rgba="0.792156862745098 0.819607843137255 0.933333333333333 1" />
      </material>
    </visual>
    <collision>
      <origin
        xyz="0 0 0"
        rpy="0 0 0" />
      <geometry>
        <mesh
          filename="./meshes/right_pinky_tactile_2.STL" />
      </geometry>
    </collision>
  </link>
  <joint
    name="right_pinky_j3_sensor"
    type="fixed">
    <origin
      xyz="0 0 0"
      rpy="0 0 0" />
    <parent
      link="right_pinky_link_3" />
    <child
      link="right_pinky_tactile_2" />
    <axis
      xyz="0 0 0" />
  </joint>
  <link
    name="right_pinky_pad">
    <inertial>
      <origin
        xyz="-0.016 -0.0079000000000001 -1.52190425529997E-05"
        rpy="0 0 0" />
      <mass
        value="8.20481262582142E-06" />
      <inertia
        ixx="2.67867788925156E-12"
        ixy="-4.96754391548075E-28"
        ixz="-6.1418050833409E-28"
        iyy="2.76292091095751E-12"
        iyz="9.76652497333542E-28"
        izz="4.1445278237637E-12" />
    </inertial>
    <visual>
      <origin
        xyz="0 0 0"
        rpy="0 0 0" />
      <geometry>
        <mesh
          filename="./meshes/right_pinky_pad.STL" />
      </geometry>
      <material
        name="">
        <color
          rgba="0.866666666666667 0.866666666666667 0.890196078431372 1" />
      </material>
    </visual>
    <collision>
      <origin
        xyz="0 0 0"
        rpy="0 0 0" />
      <geometry>
        <mesh
          filename="./meshes/right_pinky_pad.STL" />
      </geometry>
    </collision>
  </link>
  <joint
    name="right_pinky_pad"
    type="fixed">
    <origin
      xyz="0.0159962306453115 0.00790762955265271 0"
      rpy="0 0 0.000476903207341931" />
    <parent
      link="right_pinky_link_3" />
    <child
      link="right_pinky_pad" />
    <axis
      xyz="0 0 0" />
  </joint>
  <link
    name="right_pinky_tip">
    <inertial>
      <origin
        xyz="-0.028 -1.77809156287623E-16 -1.52190425530205E-05"
        rpy="0 0 0" />
      <mass
        value="8.20481262582146E-06" />
      <inertia
        ixx="2.67867788925158E-12"
        ixy="-5.91688445656393E-28"
        ixz="1.93105376242371E-27"
        iyy="2.76292091095753E-12"
        iyz="-2.78549247678555E-28"
        izz="4.14452782376372E-12" />
    </inertial>
    <visual>
      <origin
        xyz="0 0 0"
        rpy="0 0 0" />
      <geometry>
        <mesh
          filename="./meshes/right_pinky_tip.STL" />
      </geometry>
      <material
        name="">
        <color
          rgba="0.866666666666667 0.866666666666667 0.890196078431372 1" />
      </material>
    </visual>
    <collision>
      <origin
        xyz="0 0 0"
        rpy="0 0 0" />
      <geometry>
        <mesh
          filename="./meshes/right_pinky_tip.STL" />
      </geometry>
    </collision>
  </link>
  <joint
    name="right_pinky_tip"
    type="fixed">
    <origin
      xyz="0.0279999968158867 1.33532892995824E-05 0"
      rpy="0 0 0.000476903207341931" />
    <parent
      link="right_pinky_link_3" />
    <child
      link="right_pinky_tip" />
    <axis
      xyz="0 0 0" />
  </joint>
</robot>
